2020-08-25 13:21:12,648 INFO     [views.py:20] Trying to get User Login Data....
2020-08-25 13:21:12,651 INFO     [views.py:23] Successfully got the User Login Data  201
2020-08-25 13:21:33,527 INFO     [views.py:135] Trying: GET: PYQ Data
2020-08-25 13:21:33,528 INFO     [views.py:152] Successful: GET: PYQ Data
2020-08-25 13:22:45,826 INFO     [views.py:43] Trying: GET: User data by rollNumber MT2019120
2020-08-25 13:22:45,831 INFO     [views.py:53] Successful: GET: User data by rollNumber MT2019120
2020-08-25 13:22:54,759 INFO     [views.py:135] Trying: GET: PYQ Data
2020-08-25 13:22:54,759 INFO     [views.py:152] Successful: GET: PYQ Data
2020-08-25 13:22:57,71 INFO     [views.py:157] Trying: GET: PYQ by id 2
2020-08-25 13:22:57,367 INFO     [views.py:176] Successful: GET: PYQ by id 2
2020-08-25 13:22:57,446 INFO     [views.py:208] Trying: GET: Comments for PYQ by id 2
2020-08-25 13:22:57,448 INFO     [views.py:212] Successful: GET: Comments for PYQ by id 2
2020-08-25 13:23:03,449 INFO     [views.py:68] Trying: GET: Interview Exp Data
2020-08-25 13:23:03,450 INFO     [views.py:71] Successful: GET: Interview Exp Data
2020-08-25 13:23:07,443 INFO     [views.py:68] Trying: GET: Interview Exp Data
2020-08-25 13:23:07,443 INFO     [views.py:71] Successful: GET: Interview Exp Data
2020-08-25 13:23:22,964 INFO     [views.py:135] Trying: GET: PYQ Data
2020-08-25 13:23:22,964 INFO     [views.py:152] Successful: GET: PYQ Data
2020-08-25 13:23:24,665 INFO     [views.py:157] Trying: GET: PYQ by id 2
2020-08-25 13:23:24,669 INFO     [views.py:176] Successful: GET: PYQ by id 2
2020-08-25 13:23:24,749 INFO     [views.py:208] Trying: GET: Comments for PYQ by id 2
2020-08-25 13:23:24,750 INFO     [views.py:212] Successful: GET: Comments for PYQ by id 2
2020-08-25 13:23:28,823 INFO     [views.py:216] Trying: POST: Comments for PYQ by id 2
2020-08-25 13:23:30,490 INFO     [views.py:221] Successful: POST: Comments for PYQ by id 2, status 201
2020-08-25 13:23:30,498 INFO     [views.py:208] Trying: GET: Comments for PYQ by id 2
2020-08-25 13:23:30,499 INFO     [views.py:212] Successful: GET: Comments for PYQ by id 2
2020-08-25 13:24:06,600 INFO     [views.py:43] Trying: GET: User data by rollNumber MT2019114
2020-08-25 13:24:06,604 INFO     [views.py:53] Successful: GET: User data by rollNumber MT2019114
2020-08-25 13:25:48,843 INFO     [views.py:43] Trying: GET: User data by rollNumber MT2019120
2020-08-25 13:25:48,851 INFO     [views.py:53] Successful: GET: User data by rollNumber MT2019120
2020-08-25 13:26:40,164 INFO     [views.py:135] Trying: GET: PYQ Data
2020-08-25 13:26:40,166 INFO     [views.py:152] Successful: GET: PYQ Data
2020-08-30 08:06:24,465 INFO     [views.py:43] Trying: GET: User data by rollNumber MT2019120
2020-08-30 08:06:24,555 INFO     [views.py:53] Successful: GET: User data by rollNumber MT2019120
2020-08-30 08:06:27,605 INFO     [views.py:135] Trying: GET: PYQ Data
2020-08-30 08:06:27,605 INFO     [views.py:152] Successful: GET: PYQ Data
2020-08-30 08:13:47,114 INFO     [views.py:135] Trying: GET: PYQ Data
2020-08-30 08:13:47,153 INFO     [views.py:152] Successful: GET: PYQ Data
2020-08-30 08:14:19,772 INFO     [views.py:135] Trying: GET: PYQ Data
2020-08-30 08:14:19,772 INFO     [views.py:152] Successful: GET: PYQ Data
2020-08-30 08:15:21,379 INFO     [views.py:135] Trying: GET: PYQ Data
2020-08-30 08:15:21,379 INFO     [views.py:152] Successful: GET: PYQ Data
2020-08-30 08:16:55,338 INFO     [views.py:135] Trying: GET: PYQ Data
2020-08-30 08:16:55,340 INFO     [views.py:152] Successful: GET: PYQ Data
2020-08-30 08:17:45,78 INFO     [views.py:135] Trying: GET: PYQ Data
2020-08-30 08:17:45,85 INFO     [views.py:152] Successful: GET: PYQ Data
2020-08-30 08:18:21,544 INFO     [views.py:135] Trying: GET: PYQ Data
2020-08-30 08:18:21,545 INFO     [views.py:152] Successful: GET: PYQ Data
2020-08-30 08:18:30,682 INFO     [views.py:68] Trying: GET: Interview Exp Data
2020-08-30 08:18:30,682 INFO     [views.py:71] Successful: GET: Interview Exp Data
2020-08-30 08:18:34,293 INFO     [views.py:68] Trying: GET: Interview Exp Data
2020-08-30 08:18:34,293 INFO     [views.py:71] Successful: GET: Interview Exp Data
2020-08-30 08:18:38,605 INFO     [views.py:135] Trying: GET: PYQ Data
2020-08-30 08:18:38,606 INFO     [views.py:152] Successful: GET: PYQ Data
2020-08-30 08:18:57,595 INFO     [views.py:157] Trying: GET: PYQ by id 2
2020-08-30 08:18:57,602 INFO     [views.py:176] Successful: GET: PYQ by id 2
2020-08-30 08:18:58,247 INFO     [views.py:208] Trying: GET: Comments for PYQ by id 2
2020-08-30 08:18:58,248 INFO     [views.py:212] Successful: GET: Comments for PYQ by id 2
2020-08-30 08:19:11,859 INFO     [views.py:68] Trying: GET: Interview Exp Data
2020-08-30 08:19:11,859 INFO     [views.py:71] Successful: GET: Interview Exp Data
2020-08-30 08:19:20,239 INFO     [views.py:135] Trying: GET: PYQ Data
2020-08-30 08:19:20,239 INFO     [views.py:152] Successful: GET: PYQ Data
2020-08-30 08:19:23,825 INFO     [views.py:135] Trying: GET: PYQ Data
2020-08-30 08:19:23,826 INFO     [views.py:152] Successful: GET: PYQ Data
2020-08-30 08:20:15,668 INFO     [views.py:181] Trying: POST: PYQ
2020-08-30 08:20:18,634 INFO     [views.py:185] Successful: POST: PYQ, status 201
2020-08-30 08:20:22,557 INFO     [views.py:135] Trying: GET: PYQ Data
2020-08-30 08:20:22,558 INFO     [views.py:152] Successful: GET: PYQ Data
2020-08-30 08:20:24,690 INFO     [views.py:157] Trying: GET: PYQ by id 3
2020-08-30 08:20:24,692 INFO     [views.py:176] Successful: GET: PYQ by id 3
2020-08-30 08:20:24,751 INFO     [views.py:208] Trying: GET: Comments for PYQ by id 3
2020-08-30 08:20:24,752 INFO     [views.py:212] Successful: GET: Comments for PYQ by id 3
2020-08-30 08:21:27,893 INFO     [views.py:135] Trying: GET: PYQ Data
2020-08-30 08:21:27,894 INFO     [views.py:152] Successful: GET: PYQ Data
2020-08-30 08:21:28,128 INFO     [views.py:157] Trying: GET: PYQ by id 3
2020-08-30 08:21:28,130 INFO     [views.py:176] Successful: GET: PYQ by id 3
2020-08-30 08:21:28,349 INFO     [views.py:208] Trying: GET: Comments for PYQ by id 3
2020-08-30 08:21:28,350 INFO     [views.py:212] Successful: GET: Comments for PYQ by id 3
2020-08-30 08:22:26,398 INFO     [views.py:135] Trying: GET: PYQ Data
2020-08-30 08:22:26,399 INFO     [views.py:152] Successful: GET: PYQ Data
2020-08-30 08:22:26,664 INFO     [views.py:157] Trying: GET: PYQ by id 3
2020-08-30 08:22:26,667 INFO     [views.py:176] Successful: GET: PYQ by id 3
2020-08-30 08:22:26,762 INFO     [views.py:208] Trying: GET: Comments for PYQ by id 3
2020-08-30 08:22:26,766 INFO     [views.py:212] Successful: GET: Comments for PYQ by id 3
2020-08-30 08:22:49,208 INFO     [views.py:68] Trying: GET: Interview Exp Data
2020-08-30 08:22:49,208 INFO     [views.py:71] Successful: GET: Interview Exp Data
2020-08-30 08:39:13,943 INFO     [views.py:135] Trying: GET: PYQ Data
2020-08-30 08:39:13,943 INFO     [views.py:152] Successful: GET: PYQ Data
2020-08-30 08:40:40,626 INFO     [views.py:135] Trying: GET: PYQ Data
2020-08-30 08:40:40,626 INFO     [views.py:152] Successful: GET: PYQ Data
2020-08-30 08:40:45,485 WARNING  [log.py:228] Method Not Allowed: /getData/2/
2020-08-30 08:40:58,80 INFO     [views.py:135] Trying: GET: PYQ Data
2020-08-30 08:40:58,80 INFO     [views.py:152] Successful: GET: PYQ Data
2020-08-30 08:41:58,320 INFO     [views.py:135] Trying: GET: PYQ Data
2020-08-30 08:41:58,321 INFO     [views.py:152] Successful: GET: PYQ Data
2020-08-30 08:42:00,263 INFO     [views.py:164] Trying: PATCH: PYQ by id 2
2020-08-30 08:42:00,263 INFO     [views.py:157] Trying: GET: PYQ by id 2
2020-08-30 08:42:02,610 INFO     [views.py:170] Successful: PATCH: PYQ by id 2, status 201
2020-08-30 08:42:13,365 INFO     [views.py:135] Trying: GET: PYQ Data
2020-08-30 08:42:13,366 INFO     [views.py:152] Successful: GET: PYQ Data
2020-08-30 08:42:18,37 INFO     [views.py:135] Trying: GET: PYQ Data
2020-08-30 08:42:18,37 INFO     [views.py:152] Successful: GET: PYQ Data
2020-08-30 08:42:29,206 INFO     [views.py:157] Trying: GET: PYQ by id 2
2020-08-30 08:42:29,209 INFO     [views.py:176] Successful: GET: PYQ by id 2
2020-08-30 08:42:29,254 INFO     [views.py:208] Trying: GET: Comments for PYQ by id 2
2020-08-30 08:42:29,255 INFO     [views.py:212] Successful: GET: Comments for PYQ by id 2
2020-08-30 08:42:31,439 WARNING  [log.py:228] Method Not Allowed: /patchData/2/
2020-08-30 08:43:52,111 INFO     [views.py:157] Trying: GET: PYQ by id 2
2020-08-30 08:43:52,114 INFO     [views.py:176] Successful: GET: PYQ by id 2
2020-08-30 08:43:52,224 INFO     [views.py:208] Trying: GET: Comments for PYQ by id 2
2020-08-30 08:43:52,226 INFO     [views.py:212] Successful: GET: Comments for PYQ by id 2
2020-08-30 08:44:27,610 INFO     [views.py:164] Trying: PATCH: PYQ by id 2
2020-08-30 08:44:27,610 INFO     [views.py:157] Trying: GET: PYQ by id 2
2020-08-30 08:44:29,359 INFO     [views.py:170] Successful: PATCH: PYQ by id 2, status 201
2020-08-30 08:46:00,247 INFO     [views.py:157] Trying: GET: PYQ by id 2
2020-08-30 08:46:00,252 INFO     [views.py:176] Successful: GET: PYQ by id 2
2020-08-30 08:46:00,397 INFO     [views.py:208] Trying: GET: Comments for PYQ by id 2
2020-08-30 08:46:00,416 INFO     [views.py:212] Successful: GET: Comments for PYQ by id 2
2020-08-30 08:46:10,416 INFO     [views.py:68] Trying: GET: Interview Exp Data
2020-08-30 08:46:10,417 INFO     [views.py:71] Successful: GET: Interview Exp Data
2020-08-30 08:46:14,188 INFO     [views.py:68] Trying: GET: Interview Exp Data
2020-08-30 08:46:14,189 INFO     [views.py:71] Successful: GET: Interview Exp Data
2020-08-30 08:46:17,652 INFO     [views.py:135] Trying: GET: PYQ Data
2020-08-30 08:46:17,652 INFO     [views.py:152] Successful: GET: PYQ Data
2020-08-30 08:46:19,914 INFO     [views.py:164] Trying: PATCH: PYQ by id 3
2020-08-30 08:46:19,914 INFO     [views.py:157] Trying: GET: PYQ by id 3
2020-08-30 08:46:20,56 INFO     [views.py:170] Successful: PATCH: PYQ by id 3, status 201
2020-08-30 08:46:27,823 INFO     [views.py:135] Trying: GET: PYQ Data
2020-08-30 08:46:27,828 INFO     [views.py:152] Successful: GET: PYQ Data
2020-08-30 10:37:24,384 INFO     [views.py:43] Trying: GET: User data by rollNumber MT2019120
2020-08-30 10:37:24,387 INFO     [views.py:53] Successful: GET: User data by rollNumber MT2019120
2020-08-30 10:37:29,391 INFO     [views.py:135] Trying: GET: PYQ Data
2020-08-30 10:37:29,392 INFO     [views.py:152] Successful: GET: PYQ Data
2020-08-30 10:37:33,173 INFO     [views.py:157] Trying: GET: PYQ by id 2
2020-08-30 10:37:33,176 INFO     [views.py:176] Successful: GET: PYQ by id 2
2020-08-30 10:37:33,202 INFO     [views.py:208] Trying: GET: Comments for PYQ by id 2
2020-08-30 10:37:33,204 INFO     [views.py:212] Successful: GET: Comments for PYQ by id 2
2020-08-30 10:37:35,143 INFO     [views.py:164] Trying: PATCH: PYQ by id 2
2020-08-30 10:37:35,144 INFO     [views.py:157] Trying: GET: PYQ by id 2
2020-08-30 10:37:35,359 INFO     [views.py:170] Successful: PATCH: PYQ by id 2, status 201
2020-08-30 10:37:55,335 INFO     [autoreload.py:236] /home/sravya/SPEW/sem3/SCP-backened/SCP/settings.py changed, reloading.
2020-08-30 10:38:05,480 INFO     [autoreload.py:236] /home/sravya/SPEW/sem3/SCP-backened/SCP/settings.py changed, reloading.
2020-08-30 10:38:20,856 INFO     [autoreload.py:236] /home/sravya/SPEW/sem3/SCP-backened/SCP/settings.py changed, reloading.
2020-08-30 10:38:34,856 INFO     [views.py:164] Trying: PATCH: PYQ by id 2
2020-08-30 10:38:34,857 INFO     [views.py:157] Trying: GET: PYQ by id 2
2020-08-30 10:38:35,389 INFO     [views.py:170] Successful: PATCH: PYQ by id 2, status 201
2020-08-30 10:38:38,111 INFO     [views.py:157] Trying: GET: PYQ by id 2
2020-08-30 10:38:38,115 INFO     [views.py:176] Successful: GET: PYQ by id 2
2020-08-30 10:38:38,163 INFO     [views.py:208] Trying: GET: Comments for PYQ by id 2
2020-08-30 10:38:38,166 INFO     [views.py:212] Successful: GET: Comments for PYQ by id 2
2020-08-30 10:38:40,409 INFO     [views.py:164] Trying: PATCH: PYQ by id 2
2020-08-30 10:38:40,702 INFO     [views.py:157] Trying: GET: PYQ by id 2
2020-08-30 10:38:40,801 INFO     [views.py:170] Successful: PATCH: PYQ by id 2, status 201
2020-08-30 10:39:35,118 INFO     [views.py:43] Trying: GET: User data by rollNumber MT2019120
2020-08-30 10:39:35,120 INFO     [views.py:53] Successful: GET: User data by rollNumber MT2019120
2020-08-30 10:39:37,149 INFO     [views.py:135] Trying: GET: PYQ Data
2020-08-30 10:39:37,150 INFO     [views.py:152] Successful: GET: PYQ Data
2020-08-30 10:39:39,706 INFO     [views.py:157] Trying: GET: PYQ by id 3
2020-08-30 10:39:39,709 INFO     [views.py:176] Successful: GET: PYQ by id 3
2020-08-30 10:39:39,759 INFO     [views.py:208] Trying: GET: Comments for PYQ by id 3
2020-08-30 10:39:39,760 INFO     [views.py:212] Successful: GET: Comments for PYQ by id 3
2020-08-30 10:39:41,588 INFO     [views.py:164] Trying: PATCH: PYQ by id 3
2020-08-30 10:39:41,588 INFO     [views.py:157] Trying: GET: PYQ by id 3
2020-08-30 10:39:45,929 INFO     [views.py:170] Successful: PATCH: PYQ by id 3, status 201
2020-08-30 10:40:04,231 INFO     [views.py:157] Trying: GET: PYQ by id 3
2020-08-30 10:40:04,235 INFO     [views.py:176] Successful: GET: PYQ by id 3
2020-08-30 10:40:04,286 INFO     [views.py:208] Trying: GET: Comments for PYQ by id 3
2020-08-30 10:40:04,287 INFO     [views.py:212] Successful: GET: Comments for PYQ by id 3
2020-08-30 10:40:46,334 INFO     [autoreload.py:236] /home/sravya/SPEW/sem3/SCP-backened/SCP/settings.py changed, reloading.
2020-08-30 10:40:52,954 INFO     [autoreload.py:236] /home/sravya/SPEW/sem3/SCP-backened/SCP/settings.py changed, reloading.
2020-08-30 10:41:33,916 INFO     [views.py:157] Trying: GET: PYQ by id 3
2020-08-30 10:41:33,923 INFO     [views.py:176] Successful: GET: PYQ by id 3
2020-08-30 10:41:33,970 INFO     [views.py:208] Trying: GET: Comments for PYQ by id 3
2020-08-30 10:41:33,971 INFO     [views.py:212] Successful: GET: Comments for PYQ by id 3
2020-08-30 10:41:53,337 INFO     [views.py:157] Trying: GET: PYQ by id 3
2020-08-30 10:41:53,339 INFO     [views.py:176] Successful: GET: PYQ by id 3
2020-08-30 10:41:53,407 INFO     [views.py:208] Trying: GET: Comments for PYQ by id 3
2020-08-30 10:41:53,408 INFO     [views.py:212] Successful: GET: Comments for PYQ by id 3
2020-08-30 10:41:55,738 INFO     [views.py:164] Trying: PATCH: PYQ by id 3
2020-08-30 10:41:55,738 INFO     [views.py:157] Trying: GET: PYQ by id 3
2020-08-30 10:41:56,286 INFO     [views.py:170] Successful: PATCH: PYQ by id 3, status 201
2020-08-30 10:42:41,478 INFO     [autoreload.py:236] /home/sravya/SPEW/sem3/SCP-backened/SCP/settings.py changed, reloading.
2020-08-30 10:42:52,427 INFO     [autoreload.py:236] /home/sravya/SPEW/sem3/SCP-backened/SCP/settings.py changed, reloading.
2020-08-30 10:43:11,359 INFO     [autoreload.py:236] /home/sravya/SPEW/sem3/SCP-backened/SCP/settings.py changed, reloading.
2020-08-30 10:46:20,168 INFO     [views.py:68] Trying: GET: Interview Exp Data
2020-08-30 10:46:20,169 INFO     [views.py:71] Successful: GET: Interview Exp Data
2020-08-30 10:46:41,572 INFO     [views.py:75] Trying: POST: Interview Exp Data
2020-08-30 10:46:45,421 INFO     [views.py:79] Successful: POST: Interview Exp Data, status 201
2020-08-30 10:46:47,739 INFO     [views.py:68] Trying: GET: Interview Exp Data
2020-08-30 10:46:47,740 INFO     [views.py:71] Successful: GET: Interview Exp Data
2020-08-30 10:46:52,345 INFO     [views.py:68] Trying: GET: Interview Exp Data
2020-08-30 10:46:52,347 INFO     [views.py:71] Successful: GET: Interview Exp Data
2020-08-30 10:46:54,969 INFO     [views.py:103] Trying: PATCH: Interview Exp by id 2
2020-08-30 10:46:54,970 INFO     [views.py:90] Trying: GET: Interview Exp by id 2
2020-08-30 10:46:58,155 INFO     [views.py:109] Successful: PATCH: Interview Exp by id 2, status 201
2020-08-30 10:53:29,192 INFO     [views.py:43] Trying: GET: User data by rollNumber MT2019120
2020-08-30 10:53:29,194 INFO     [views.py:53] Successful: GET: User data by rollNumber MT2019120
2020-08-30 11:18:07,378 INFO     [views.py:43] Trying: GET: User data by rollNumber MT2019120
2020-08-30 11:18:07,380 INFO     [views.py:53] Successful: GET: User data by rollNumber MT2019120
2020-08-30 11:18:42,992 INFO     [views.py:135] Trying: GET: PYQ Data
2020-08-30 11:18:42,992 INFO     [views.py:152] Successful: GET: PYQ Data
2020-08-30 11:20:25,90 INFO     [views.py:135] Trying: GET: PYQ Data
2020-08-30 11:20:25,90 INFO     [views.py:152] Successful: GET: PYQ Data
2020-08-30 11:22:26,52 INFO     [views.py:43] Trying: GET: User data by rollNumber MT2019114
2020-08-30 11:22:26,60 INFO     [views.py:53] Successful: GET: User data by rollNumber MT2019114
2020-08-30 11:22:38,451 INFO     [views.py:135] Trying: GET: PYQ Data
2020-08-30 11:22:38,452 INFO     [views.py:152] Successful: GET: PYQ Data
2020-08-30 13:36:51,854 INFO     [views.py:43] Trying: GET: User data by rollNumber MT2019114
2020-08-30 13:36:51,858 INFO     [views.py:53] Successful: GET: User data by rollNumber MT2019114
2020-08-30 13:55:36,743 INFO     [views.py:68] Trying: GET: Interview Exp Data
2020-08-30 13:55:36,743 INFO     [views.py:71] Successful: GET: Interview Exp Data
2020-08-30 13:55:41,150 INFO     [views.py:90] Trying: GET: Interview Exp by id 2
2020-08-30 13:55:41,153 INFO     [views.py:99] Successful: GET: Interview Exp by id 2
2020-08-30 13:55:41,241 INFO     [views.py:240] Trying: GET: Comments for Interview Exp by id 2
2020-08-30 13:55:41,242 INFO     [views.py:244] Successful: GET: Comments for Interview Exp by id 2
2020-08-30 16:35:58,835 INFO     [views.py:43] Trying: GET: User data by rollNumber MT2019120
2020-08-30 16:35:58,853 INFO     [views.py:53] Successful: GET: User data by rollNumber MT2019120
2020-08-30 16:36:19,387 INFO     [views.py:68] Trying: GET: Interview Exp Data
2020-08-30 16:36:19,388 INFO     [views.py:71] Successful: GET: Interview Exp Data
2020-08-30 16:36:36,944 INFO     [views.py:135] Trying: GET: PYQ Data
2020-08-30 16:36:36,945 INFO     [views.py:152] Successful: GET: PYQ Data
2020-08-30 16:36:39,690 INFO     [views.py:68] Trying: GET: Interview Exp Data
2020-08-30 16:36:39,695 INFO     [views.py:71] Successful: GET: Interview Exp Data
2020-08-30 16:36:42,995 INFO     [views.py:68] Trying: GET: Interview Exp Data
2020-08-30 16:36:42,996 INFO     [views.py:71] Successful: GET: Interview Exp Data
2020-08-31 06:45:14,349 INFO     [views.py:43] Trying: GET: User data by rollNumber MT2019120
2020-08-31 06:45:16,90 INFO     [views.py:53] Successful: GET: User data by rollNumber MT2019120
2020-08-31 06:45:21,287 INFO     [views.py:135] Trying: GET: PYQ Data
2020-08-31 06:45:21,288 INFO     [views.py:152] Successful: GET: PYQ Data
2020-08-31 06:45:40,841 INFO     [views.py:157] Trying: GET: PYQ by id 2
2020-08-31 06:45:40,846 INFO     [views.py:176] Successful: GET: PYQ by id 2
2020-08-31 06:45:41,171 INFO     [views.py:208] Trying: GET: Comments for PYQ by id 2
2020-08-31 06:45:41,172 INFO     [views.py:212] Successful: GET: Comments for PYQ by id 2
2020-08-31 06:46:08,79 INFO     [views.py:68] Trying: GET: Interview Exp Data
2020-08-31 06:46:08,79 INFO     [views.py:71] Successful: GET: Interview Exp Data
2020-08-31 06:46:13,570 INFO     [views.py:90] Trying: GET: Interview Exp by id 2
2020-08-31 06:46:13,572 INFO     [views.py:99] Successful: GET: Interview Exp by id 2
2020-08-31 06:46:13,631 INFO     [views.py:240] Trying: GET: Comments for Interview Exp by id 2
2020-08-31 06:46:13,632 INFO     [views.py:244] Successful: GET: Comments for Interview Exp by id 2
2020-08-31 06:46:40,545 INFO     [views.py:103] Trying: PATCH: Interview Exp by id 2
2020-08-31 06:46:40,547 INFO     [views.py:90] Trying: GET: Interview Exp by id 2
2020-08-31 06:46:40,802 INFO     [views.py:109] Successful: PATCH: Interview Exp by id 2, status 201
2020-08-31 06:46:46,531 INFO     [views.py:90] Trying: GET: Interview Exp by id 2
2020-08-31 06:46:46,534 INFO     [views.py:99] Successful: GET: Interview Exp by id 2
2020-08-31 06:46:46,574 INFO     [views.py:240] Trying: GET: Comments for Interview Exp by id 2
2020-08-31 06:46:46,574 INFO     [views.py:244] Successful: GET: Comments for Interview Exp by id 2
2020-08-31 06:46:49,662 INFO     [views.py:90] Trying: GET: Interview Exp by id 2
2020-08-31 06:46:49,665 INFO     [views.py:99] Successful: GET: Interview Exp by id 2
2020-08-31 06:46:49,691 INFO     [views.py:240] Trying: GET: Comments for Interview Exp by id 2
2020-08-31 06:46:49,692 INFO     [views.py:244] Successful: GET: Comments for Interview Exp by id 2
2020-09-22 11:58:06,327 INFO     [autoreload.py:222] C:\Users\Sahil Arora\Desktop\SCP-B\SCP-backened\SCP\urls.py changed, reloading.
2020-09-22 11:58:19,482 WARNING  [log.py:228] Not Found: /password_reset/
2020-09-22 11:58:20,318 WARNING  [log.py:228] Not Found: /favicon.ico
2020-09-22 12:03:39,165 INFO     [autoreload.py:222] C:\Users\Sahil Arora\Desktop\SCP-B\SCP-backened\SCP\urls.py changed, reloading.
2020-09-22 12:06:02,728 INFO     [autoreload.py:222] C:\Users\Sahil Arora\Desktop\SCP-B\SCP-backened\SCP\settings.py changed, reloading.
2020-09-22 12:12:33,982 INFO     [autoreload.py:222] C:\Users\Sahil Arora\Desktop\SCP-B\SCP-backened\SCP\settings.py changed, reloading.
2020-09-23 20:25:07,620 WARNING  [log.py:228] Not Found: /
2020-09-23 20:25:12,753 WARNING  [log.py:228] Not Found: /favicon.ico
2020-09-23 21:02:00,548 WARNING  [log.py:228] Not Found: /password_reset/
2020-09-23 22:49:03,204 ERROR    [log.py:228] Internal Server Error: /confirmEmailID/
Traceback (most recent call last):
  File "C:\Users\Sahil Arora\Desktop\SCP-B\venv\lib\site-packages\django\core\handlers\exception.py", line 34, in inner
    response = get_response(request)
  File "C:\Users\Sahil Arora\Desktop\SCP-B\venv\lib\site-packages\django\core\handlers\base.py", line 115, in _get_response
    response = self.process_exception_by_middleware(e, request)
  File "C:\Users\Sahil Arora\Desktop\SCP-B\venv\lib\site-packages\django\core\handlers\base.py", line 113, in _get_response
    response = wrapped_callback(request, *callback_args, **callback_kwargs)
  File "C:\Users\Sahil Arora\Desktop\SCP-B\venv\lib\site-packages\django\views\decorators\csrf.py", line 54, in wrapped_view
    return view_func(*args, **kwargs)
  File "C:\Users\Sahil Arora\Desktop\SCP-B\venv\lib\site-packages\django\views\generic\base.py", line 71, in view
    return self.dispatch(request, *args, **kwargs)
  File "C:\Users\Sahil Arora\Desktop\SCP-B\venv\lib\site-packages\rest_framework\views.py", line 507, in dispatch
    self.response = self.finalize_response(request, response, *args, **kwargs)
  File "C:\Users\Sahil Arora\Desktop\SCP-B\venv\lib\site-packages\rest_framework\views.py", line 422, in finalize_response
    % type(response)
AssertionError: Expected a `Response`, `HttpResponse` or `HttpStreamingResponse` to be returned from the view, but received a `<class 'int'>`
2020-09-23 22:52:53,913 INFO     [autoreload.py:222] C:\Users\Sahil Arora\Desktop\SCP-B\SCP-backened\SCPapp\views.py changed, reloading.
2020-09-23 22:57:48,273 INFO     [autoreload.py:222] C:\Users\Sahil Arora\Desktop\SCP-B\SCP-backened\SCPapp\views.py changed, reloading.
2020-09-23 22:58:18,272 ERROR    [log.py:228] Internal Server Error: /confirmEmailID/
Traceback (most recent call last):
  File "C:\Users\Sahil Arora\Desktop\SCP-B\venv\lib\site-packages\django\core\handlers\exception.py", line 34, in inner
    response = get_response(request)
  File "C:\Users\Sahil Arora\Desktop\SCP-B\venv\lib\site-packages\django\core\handlers\base.py", line 115, in _get_response
    response = self.process_exception_by_middleware(e, request)
  File "C:\Users\Sahil Arora\Desktop\SCP-B\venv\lib\site-packages\django\core\handlers\base.py", line 113, in _get_response
    response = wrapped_callback(request, *callback_args, **callback_kwargs)
  File "C:\Users\Sahil Arora\Desktop\SCP-B\venv\lib\site-packages\django\views\decorators\csrf.py", line 54, in wrapped_view
    return view_func(*args, **kwargs)
  File "C:\Users\Sahil Arora\Desktop\SCP-B\venv\lib\site-packages\django\views\generic\base.py", line 71, in view
    return self.dispatch(request, *args, **kwargs)
  File "C:\Users\Sahil Arora\Desktop\SCP-B\venv\lib\site-packages\rest_framework\views.py", line 505, in dispatch
    response = self.handle_exception(exc)
  File "C:\Users\Sahil Arora\Desktop\SCP-B\venv\lib\site-packages\rest_framework\views.py", line 465, in handle_exception
    self.raise_uncaught_exception(exc)
  File "C:\Users\Sahil Arora\Desktop\SCP-B\venv\lib\site-packages\rest_framework\views.py", line 476, in raise_uncaught_exception
    raise exc
  File "C:\Users\Sahil Arora\Desktop\SCP-B\venv\lib\site-packages\rest_framework\views.py", line 502, in dispatch
    response = handler(request, *args, **kwargs)
  File "C:\Users\Sahil Arora\Desktop\SCP-B\SCP-backened\SCPapp\views.py", line 29, in post
    self.otpgen()
TypeError: otpgen() takes 0 positional arguments but 1 was given
2020-09-23 22:59:14,405 INFO     [autoreload.py:222] C:\Users\Sahil Arora\Desktop\SCP-B\SCP-backened\SCPapp\views.py changed, reloading.
2020-09-23 22:59:47,893 INFO     [autoreload.py:222] C:\Users\Sahil Arora\Desktop\SCP-B\SCP-backened\SCPapp\views.py changed, reloading.
2020-09-23 23:01:08,595 INFO     [autoreload.py:222] C:\Users\Sahil Arora\Desktop\SCP-B\SCP-backened\SCPapp\views.py changed, reloading.
2020-09-23 23:01:23,415 ERROR    [log.py:228] Internal Server Error: /confirmEmailID/
Traceback (most recent call last):
  File "C:\Users\Sahil Arora\Desktop\SCP-B\venv\lib\site-packages\django\core\handlers\exception.py", line 34, in inner
    response = get_response(request)
  File "C:\Users\Sahil Arora\Desktop\SCP-B\venv\lib\site-packages\django\core\handlers\base.py", line 115, in _get_response
    response = self.process_exception_by_middleware(e, request)
  File "C:\Users\Sahil Arora\Desktop\SCP-B\venv\lib\site-packages\django\core\handlers\base.py", line 113, in _get_response
    response = wrapped_callback(request, *callback_args, **callback_kwargs)
  File "C:\Users\Sahil Arora\Desktop\SCP-B\venv\lib\site-packages\django\views\decorators\csrf.py", line 54, in wrapped_view
    return view_func(*args, **kwargs)
  File "C:\Users\Sahil Arora\Desktop\SCP-B\venv\lib\site-packages\django\views\generic\base.py", line 71, in view
    return self.dispatch(request, *args, **kwargs)
  File "C:\Users\Sahil Arora\Desktop\SCP-B\venv\lib\site-packages\rest_framework\views.py", line 505, in dispatch
    response = self.handle_exception(exc)
  File "C:\Users\Sahil Arora\Desktop\SCP-B\venv\lib\site-packages\rest_framework\views.py", line 465, in handle_exception
    self.raise_uncaught_exception(exc)
  File "C:\Users\Sahil Arora\Desktop\SCP-B\venv\lib\site-packages\rest_framework\views.py", line 476, in raise_uncaught_exception
    raise exc
  File "C:\Users\Sahil Arora\Desktop\SCP-B\venv\lib\site-packages\rest_framework\views.py", line 502, in dispatch
    response = handler(request, *args, **kwargs)
  File "C:\Users\Sahil Arora\Desktop\SCP-B\SCP-backened\SCPapp\views.py", line 32, in post
    send_mail( 'SCP Demo', 'Hey Welcome! your OTP is '+  otpgen(), 'iiitbemailverify@gmail.com',
TypeError: must be str, not NoneType
2020-09-23 23:01:41,285 INFO     [autoreload.py:222] C:\Users\Sahil Arora\Desktop\SCP-B\SCP-backened\SCPapp\views.py changed, reloading.
2020-09-23 23:03:56,178 INFO     [autoreload.py:222] C:\Users\Sahil Arora\Desktop\SCP-B\SCP-backened\SCPapp\views.py changed, reloading.
2020-09-23 23:06:05,320 INFO     [autoreload.py:222] C:\Users\Sahil Arora\Desktop\SCP-B\SCP-backened\SCPapp\models.py changed, reloading.
2020-09-23 23:07:12,515 INFO     [autoreload.py:222] C:\Users\Sahil Arora\Desktop\SCP-B\SCP-backened\SCPapp\serializers.py changed, reloading.
2020-09-23 23:09:38,457 INFO     [autoreload.py:222] C:\Users\Sahil Arora\Desktop\SCP-B\SCP-backened\SCPapp\views.py changed, reloading.
2020-09-23 23:11:13,121 INFO     [autoreload.py:222] C:\Users\Sahil Arora\Desktop\SCP-B\SCP-backened\SCPapp\views.py changed, reloading.
2020-09-23 23:11:27,537 ERROR    [log.py:228] Internal Server Error: /confirmEmailID/
Traceback (most recent call last):
  File "C:\Users\Sahil Arora\Desktop\SCP-B\venv\lib\site-packages\django\core\handlers\exception.py", line 34, in inner
    response = get_response(request)
  File "C:\Users\Sahil Arora\Desktop\SCP-B\venv\lib\site-packages\django\core\handlers\base.py", line 115, in _get_response
    response = self.process_exception_by_middleware(e, request)
  File "C:\Users\Sahil Arora\Desktop\SCP-B\venv\lib\site-packages\django\core\handlers\base.py", line 113, in _get_response
    response = wrapped_callback(request, *callback_args, **callback_kwargs)
  File "C:\Users\Sahil Arora\Desktop\SCP-B\venv\lib\site-packages\django\views\decorators\csrf.py", line 54, in wrapped_view
    return view_func(*args, **kwargs)
  File "C:\Users\Sahil Arora\Desktop\SCP-B\venv\lib\site-packages\django\views\generic\base.py", line 71, in view
    return self.dispatch(request, *args, **kwargs)
  File "C:\Users\Sahil Arora\Desktop\SCP-B\venv\lib\site-packages\rest_framework\views.py", line 505, in dispatch
    response = self.handle_exception(exc)
  File "C:\Users\Sahil Arora\Desktop\SCP-B\venv\lib\site-packages\rest_framework\views.py", line 465, in handle_exception
    self.raise_uncaught_exception(exc)
  File "C:\Users\Sahil Arora\Desktop\SCP-B\venv\lib\site-packages\rest_framework\views.py", line 476, in raise_uncaught_exception
    raise exc
  File "C:\Users\Sahil Arora\Desktop\SCP-B\venv\lib\site-packages\rest_framework\views.py", line 502, in dispatch
    response = handler(request, *args, **kwargs)
  File "C:\Users\Sahil Arora\Desktop\SCP-B\SCP-backened\SCPapp\views.py", line 32, in post
    print(request.data.Email)
AttributeError: 'dict' object has no attribute 'Email'
2020-09-23 23:11:42,704 INFO     [autoreload.py:222] C:\Users\Sahil Arora\Desktop\SCP-B\SCP-backened\SCPapp\views.py changed, reloading.
2020-09-23 23:12:12,21 INFO     [autoreload.py:222] C:\Users\Sahil Arora\Desktop\SCP-B\SCP-backened\SCPapp\views.py changed, reloading.
2020-09-23 23:15:44,84 INFO     [autoreload.py:222] C:\Users\Sahil Arora\Desktop\SCP-B\SCP-backened\SCPapp\views.py changed, reloading.
2020-09-23 23:17:48,753 INFO     [autoreload.py:222] C:\Users\Sahil Arora\Desktop\SCP-B\SCP-backened\SCPapp\models.py changed, reloading.
2020-09-23 23:20:40,383 INFO     [autoreload.py:222] C:\Users\Sahil Arora\Desktop\SCP-B\SCP-backened\SCPapp\views.py changed, reloading.
2020-09-23 23:21:27,755 ERROR    [log.py:228] Internal Server Error: /confirmEmailID/
Traceback (most recent call last):
  File "C:\Users\Sahil Arora\Desktop\SCP-B\venv\lib\site-packages\django\core\handlers\exception.py", line 34, in inner
    response = get_response(request)
  File "C:\Users\Sahil Arora\Desktop\SCP-B\venv\lib\site-packages\django\core\handlers\base.py", line 115, in _get_response
    response = self.process_exception_by_middleware(e, request)
  File "C:\Users\Sahil Arora\Desktop\SCP-B\venv\lib\site-packages\django\core\handlers\base.py", line 113, in _get_response
    response = wrapped_callback(request, *callback_args, **callback_kwargs)
  File "C:\Users\Sahil Arora\Desktop\SCP-B\venv\lib\site-packages\django\views\decorators\csrf.py", line 54, in wrapped_view
    return view_func(*args, **kwargs)
  File "C:\Users\Sahil Arora\Desktop\SCP-B\venv\lib\site-packages\django\views\generic\base.py", line 71, in view
    return self.dispatch(request, *args, **kwargs)
  File "C:\Users\Sahil Arora\Desktop\SCP-B\venv\lib\site-packages\rest_framework\views.py", line 505, in dispatch
    response = self.handle_exception(exc)
  File "C:\Users\Sahil Arora\Desktop\SCP-B\venv\lib\site-packages\rest_framework\views.py", line 465, in handle_exception
    self.raise_uncaught_exception(exc)
  File "C:\Users\Sahil Arora\Desktop\SCP-B\venv\lib\site-packages\rest_framework\views.py", line 476, in raise_uncaught_exception
    raise exc
  File "C:\Users\Sahil Arora\Desktop\SCP-B\venv\lib\site-packages\rest_framework\views.py", line 502, in dispatch
    response = handler(request, *args, **kwargs)
  File "C:\Users\Sahil Arora\Desktop\SCP-B\SCP-backened\SCPapp\views.py", line 32, in post
    data=request.data+ json.dumps(str(otpgen()))
NameError: name 'json' is not defined
2020-09-23 23:22:00,197 INFO     [autoreload.py:222] C:\Users\Sahil Arora\Desktop\SCP-B\SCP-backened\SCPapp\views.py changed, reloading.
2020-09-23 23:22:08,308 ERROR    [log.py:228] Internal Server Error: /confirmEmailID/
Traceback (most recent call last):
  File "C:\Users\Sahil Arora\Desktop\SCP-B\venv\lib\site-packages\django\core\handlers\exception.py", line 34, in inner
    response = get_response(request)
  File "C:\Users\Sahil Arora\Desktop\SCP-B\venv\lib\site-packages\django\core\handlers\base.py", line 115, in _get_response
    response = self.process_exception_by_middleware(e, request)
  File "C:\Users\Sahil Arora\Desktop\SCP-B\venv\lib\site-packages\django\core\handlers\base.py", line 113, in _get_response
    response = wrapped_callback(request, *callback_args, **callback_kwargs)
  File "C:\Users\Sahil Arora\Desktop\SCP-B\venv\lib\site-packages\django\views\decorators\csrf.py", line 54, in wrapped_view
    return view_func(*args, **kwargs)
  File "C:\Users\Sahil Arora\Desktop\SCP-B\venv\lib\site-packages\django\views\generic\base.py", line 71, in view
    return self.dispatch(request, *args, **kwargs)
  File "C:\Users\Sahil Arora\Desktop\SCP-B\venv\lib\site-packages\rest_framework\views.py", line 505, in dispatch
    response = self.handle_exception(exc)
  File "C:\Users\Sahil Arora\Desktop\SCP-B\venv\lib\site-packages\rest_framework\views.py", line 465, in handle_exception
    self.raise_uncaught_exception(exc)
  File "C:\Users\Sahil Arora\Desktop\SCP-B\venv\lib\site-packages\rest_framework\views.py", line 476, in raise_uncaught_exception
    raise exc
  File "C:\Users\Sahil Arora\Desktop\SCP-B\venv\lib\site-packages\rest_framework\views.py", line 502, in dispatch
    response = handler(request, *args, **kwargs)
  File "C:\Users\Sahil Arora\Desktop\SCP-B\SCP-backened\SCPapp\views.py", line 34, in post
    data=request.data+ json.dumps(str(otpgen()))
TypeError: unsupported operand type(s) for +: 'dict' and 'str'
2020-09-23 23:22:29,215 INFO     [autoreload.py:222] C:\Users\Sahil Arora\Desktop\SCP-B\SCP-backened\SCPapp\views.py changed, reloading.
2020-09-23 23:22:44,821 ERROR    [log.py:228] Internal Server Error: /confirmEmailID/
Traceback (most recent call last):
  File "C:\Users\Sahil Arora\Desktop\SCP-B\venv\lib\site-packages\django\core\handlers\exception.py", line 34, in inner
    response = get_response(request)
  File "C:\Users\Sahil Arora\Desktop\SCP-B\venv\lib\site-packages\django\core\handlers\base.py", line 115, in _get_response
    response = self.process_exception_by_middleware(e, request)
  File "C:\Users\Sahil Arora\Desktop\SCP-B\venv\lib\site-packages\django\core\handlers\base.py", line 113, in _get_response
    response = wrapped_callback(request, *callback_args, **callback_kwargs)
  File "C:\Users\Sahil Arora\Desktop\SCP-B\venv\lib\site-packages\django\views\decorators\csrf.py", line 54, in wrapped_view
    return view_func(*args, **kwargs)
  File "C:\Users\Sahil Arora\Desktop\SCP-B\venv\lib\site-packages\django\views\generic\base.py", line 71, in view
    return self.dispatch(request, *args, **kwargs)
  File "C:\Users\Sahil Arora\Desktop\SCP-B\venv\lib\site-packages\rest_framework\views.py", line 505, in dispatch
    response = self.handle_exception(exc)
  File "C:\Users\Sahil Arora\Desktop\SCP-B\venv\lib\site-packages\rest_framework\views.py", line 465, in handle_exception
    self.raise_uncaught_exception(exc)
  File "C:\Users\Sahil Arora\Desktop\SCP-B\venv\lib\site-packages\rest_framework\views.py", line 476, in raise_uncaught_exception
    raise exc
  File "C:\Users\Sahil Arora\Desktop\SCP-B\venv\lib\site-packages\rest_framework\views.py", line 502, in dispatch
    response = handler(request, *args, **kwargs)
  File "C:\Users\Sahil Arora\Desktop\SCP-B\SCP-backened\SCPapp\views.py", line 34, in post
    data=request.data+ str(otpgen())
TypeError: unsupported operand type(s) for +: 'dict' and 'str'
2020-09-23 23:24:49,409 INFO     [autoreload.py:222] C:\Users\Sahil Arora\Desktop\SCP-B\SCP-backened\SCPapp\views.py changed, reloading.
2020-09-23 23:25:37,849 INFO     [autoreload.py:222] C:\Users\Sahil Arora\Desktop\SCP-B\SCP-backened\SCPapp\models.py changed, reloading.
2020-09-23 23:26:50,908 INFO     [autoreload.py:222] C:\Users\Sahil Arora\Desktop\SCP-B\SCP-backened\SCPapp\views.py changed, reloading.
2020-09-23 23:27:07,609 ERROR    [log.py:228] Internal Server Error: /confirmEmailID/
Traceback (most recent call last):
  File "C:\Users\Sahil Arora\Desktop\SCP-B\venv\lib\site-packages\django\core\handlers\exception.py", line 34, in inner
    response = get_response(request)
  File "C:\Users\Sahil Arora\Desktop\SCP-B\venv\lib\site-packages\django\core\handlers\base.py", line 115, in _get_response
    response = self.process_exception_by_middleware(e, request)
  File "C:\Users\Sahil Arora\Desktop\SCP-B\venv\lib\site-packages\django\core\handlers\base.py", line 113, in _get_response
    response = wrapped_callback(request, *callback_args, **callback_kwargs)
  File "C:\Users\Sahil Arora\Desktop\SCP-B\venv\lib\site-packages\django\views\decorators\csrf.py", line 54, in wrapped_view
    return view_func(*args, **kwargs)
  File "C:\Users\Sahil Arora\Desktop\SCP-B\venv\lib\site-packages\django\views\generic\base.py", line 71, in view
    return self.dispatch(request, *args, **kwargs)
  File "C:\Users\Sahil Arora\Desktop\SCP-B\venv\lib\site-packages\rest_framework\views.py", line 505, in dispatch
    response = self.handle_exception(exc)
  File "C:\Users\Sahil Arora\Desktop\SCP-B\venv\lib\site-packages\rest_framework\views.py", line 465, in handle_exception
    self.raise_uncaught_exception(exc)
  File "C:\Users\Sahil Arora\Desktop\SCP-B\venv\lib\site-packages\rest_framework\views.py", line 476, in raise_uncaught_exception
    raise exc
  File "C:\Users\Sahil Arora\Desktop\SCP-B\venv\lib\site-packages\rest_framework\views.py", line 502, in dispatch
    response = handler(request, *args, **kwargs)
  File "C:\Users\Sahil Arora\Desktop\SCP-B\SCP-backened\SCPapp\views.py", line 37, in post
    emailSerializer = emailSerializer(data=request.data)
UnboundLocalError: local variable 'emailSerializer' referenced before assignment
2020-09-23 23:28:30,458 INFO     [autoreload.py:222] C:\Users\Sahil Arora\Desktop\SCP-B\SCP-backened\SCPapp\views.py changed, reloading.
2020-09-23 23:28:45,907 ERROR    [log.py:228] Internal Server Error: /confirmEmailID/
Traceback (most recent call last):
  File "C:\Users\Sahil Arora\Desktop\SCP-B\venv\lib\site-packages\django\db\backends\utils.py", line 86, in _execute
    return self.cursor.execute(sql, params)
  File "C:\Users\Sahil Arora\Desktop\SCP-B\venv\lib\site-packages\django\db\backends\sqlite3\base.py", line 396, in execute
    return Database.Cursor.execute(self, query, params)
sqlite3.OperationalError: no such table: SCPapp_emailverify

The above exception was the direct cause of the following exception:

Traceback (most recent call last):
  File "C:\Users\Sahil Arora\Desktop\SCP-B\venv\lib\site-packages\django\core\handlers\exception.py", line 34, in inner
    response = get_response(request)
  File "C:\Users\Sahil Arora\Desktop\SCP-B\venv\lib\site-packages\django\core\handlers\base.py", line 115, in _get_response
    response = self.process_exception_by_middleware(e, request)
  File "C:\Users\Sahil Arora\Desktop\SCP-B\venv\lib\site-packages\django\core\handlers\base.py", line 113, in _get_response
    response = wrapped_callback(request, *callback_args, **callback_kwargs)
  File "C:\Users\Sahil Arora\Desktop\SCP-B\venv\lib\site-packages\django\views\decorators\csrf.py", line 54, in wrapped_view
    return view_func(*args, **kwargs)
  File "C:\Users\Sahil Arora\Desktop\SCP-B\venv\lib\site-packages\django\views\generic\base.py", line 71, in view
    return self.dispatch(request, *args, **kwargs)
  File "C:\Users\Sahil Arora\Desktop\SCP-B\venv\lib\site-packages\rest_framework\views.py", line 505, in dispatch
    response = self.handle_exception(exc)
  File "C:\Users\Sahil Arora\Desktop\SCP-B\venv\lib\site-packages\rest_framework\views.py", line 465, in handle_exception
    self.raise_uncaught_exception(exc)
  File "C:\Users\Sahil Arora\Desktop\SCP-B\venv\lib\site-packages\rest_framework\views.py", line 476, in raise_uncaught_exception
    raise exc
  File "C:\Users\Sahil Arora\Desktop\SCP-B\venv\lib\site-packages\rest_framework\views.py", line 502, in dispatch
    response = handler(request, *args, **kwargs)
  File "C:\Users\Sahil Arora\Desktop\SCP-B\SCP-backened\SCPapp\views.py", line 38, in post
    if emailVerify.is_valid():
  File "C:\Users\Sahil Arora\Desktop\SCP-B\venv\lib\site-packages\rest_framework\serializers.py", line 234, in is_valid
    self._validated_data = self.run_validation(self.initial_data)
  File "C:\Users\Sahil Arora\Desktop\SCP-B\venv\lib\site-packages\rest_framework\serializers.py", line 433, in run_validation
    value = self.to_internal_value(data)
  File "C:\Users\Sahil Arora\Desktop\SCP-B\venv\lib\site-packages\rest_framework\serializers.py", line 490, in to_internal_value
    validated_value = field.run_validation(primitive_value)
  File "C:\Users\Sahil Arora\Desktop\SCP-B\venv\lib\site-packages\rest_framework\fields.py", line 830, in run_validation
    return super().run_validation(data)
  File "C:\Users\Sahil Arora\Desktop\SCP-B\venv\lib\site-packages\rest_framework\fields.py", line 566, in run_validation
    self.run_validators(value)
  File "C:\Users\Sahil Arora\Desktop\SCP-B\venv\lib\site-packages\rest_framework\fields.py", line 588, in run_validators
    validator(value, self)
  File "C:\Users\Sahil Arora\Desktop\SCP-B\venv\lib\site-packages\rest_framework\validators.py", line 73, in __call__
    if qs_exists(queryset):
  File "C:\Users\Sahil Arora\Desktop\SCP-B\venv\lib\site-packages\rest_framework\validators.py", line 21, in qs_exists
    return queryset.exists()
  File "C:\Users\Sahil Arora\Desktop\SCP-B\venv\lib\site-packages\django\db\models\query.py", line 777, in exists
    return self.query.has_results(using=self.db)
  File "C:\Users\Sahil Arora\Desktop\SCP-B\venv\lib\site-packages\django\db\models\sql\query.py", line 537, in has_results
    return compiler.has_results()
  File "C:\Users\Sahil Arora\Desktop\SCP-B\venv\lib\site-packages\django\db\models\sql\compiler.py", line 1121, in has_results
    return bool(self.execute_sql(SINGLE))
  File "C:\Users\Sahil Arora\Desktop\SCP-B\venv\lib\site-packages\django\db\models\sql\compiler.py", line 1151, in execute_sql
    cursor.execute(sql, params)
  File "C:\Users\Sahil Arora\Desktop\SCP-B\venv\lib\site-packages\django\db\backends\utils.py", line 100, in execute
    return super().execute(sql, params)
  File "C:\Users\Sahil Arora\Desktop\SCP-B\venv\lib\site-packages\django\db\backends\utils.py", line 68, in execute
    return self._execute_with_wrappers(sql, params, many=False, executor=self._execute)
  File "C:\Users\Sahil Arora\Desktop\SCP-B\venv\lib\site-packages\django\db\backends\utils.py", line 77, in _execute_with_wrappers
    return executor(sql, params, many, context)
  File "C:\Users\Sahil Arora\Desktop\SCP-B\venv\lib\site-packages\django\db\backends\utils.py", line 86, in _execute
    return self.cursor.execute(sql, params)
  File "C:\Users\Sahil Arora\Desktop\SCP-B\venv\lib\site-packages\django\db\utils.py", line 90, in __exit__
    raise dj_exc_value.with_traceback(traceback) from exc_value
  File "C:\Users\Sahil Arora\Desktop\SCP-B\venv\lib\site-packages\django\db\backends\utils.py", line 86, in _execute
    return self.cursor.execute(sql, params)
  File "C:\Users\Sahil Arora\Desktop\SCP-B\venv\lib\site-packages\django\db\backends\sqlite3\base.py", line 396, in execute
    return Database.Cursor.execute(self, query, params)
django.db.utils.OperationalError: no such table: SCPapp_emailverify
2020-09-23 23:31:05,539 INFO     [autoreload.py:222] C:\Users\Sahil Arora\Desktop\SCP-B\SCP-backened\SCPapp\views.py changed, reloading.
2020-09-23 23:31:27,230 ERROR    [log.py:228] Internal Server Error: /confirmEmailID/
Traceback (most recent call last):
  File "C:\Users\Sahil Arora\Desktop\SCP-B\venv\lib\site-packages\django\core\handlers\exception.py", line 34, in inner
    response = get_response(request)
  File "C:\Users\Sahil Arora\Desktop\SCP-B\venv\lib\site-packages\django\core\handlers\base.py", line 115, in _get_response
    response = self.process_exception_by_middleware(e, request)
  File "C:\Users\Sahil Arora\Desktop\SCP-B\venv\lib\site-packages\django\core\handlers\base.py", line 113, in _get_response
    response = wrapped_callback(request, *callback_args, **callback_kwargs)
  File "C:\Users\Sahil Arora\Desktop\SCP-B\venv\lib\site-packages\django\views\decorators\csrf.py", line 54, in wrapped_view
    return view_func(*args, **kwargs)
  File "C:\Users\Sahil Arora\Desktop\SCP-B\venv\lib\site-packages\django\views\generic\base.py", line 71, in view
    return self.dispatch(request, *args, **kwargs)
  File "C:\Users\Sahil Arora\Desktop\SCP-B\venv\lib\site-packages\rest_framework\views.py", line 505, in dispatch
    response = self.handle_exception(exc)
  File "C:\Users\Sahil Arora\Desktop\SCP-B\venv\lib\site-packages\rest_framework\views.py", line 465, in handle_exception
    self.raise_uncaught_exception(exc)
  File "C:\Users\Sahil Arora\Desktop\SCP-B\venv\lib\site-packages\rest_framework\views.py", line 476, in raise_uncaught_exception
    raise exc
  File "C:\Users\Sahil Arora\Desktop\SCP-B\venv\lib\site-packages\rest_framework\views.py", line 502, in dispatch
    response = handler(request, *args, **kwargs)
  File "C:\Users\Sahil Arora\Desktop\SCP-B\SCP-backened\SCPapp\views.py", line 46, in get
    emailVerify = emailVerify.objects.all()
UnboundLocalError: local variable 'emailVerify' referenced before assignment
2020-09-23 23:32:05,854 INFO     [autoreload.py:222] C:\Users\Sahil Arora\Desktop\SCP-B\SCP-backened\SCPapp\views.py changed, reloading.
2020-09-23 23:32:18,208 ERROR    [log.py:228] Internal Server Error: /confirmEmailID/
Traceback (most recent call last):
  File "C:\Users\Sahil Arora\Desktop\SCP-B\venv\lib\site-packages\django\core\handlers\exception.py", line 34, in inner
    response = get_response(request)
  File "C:\Users\Sahil Arora\Desktop\SCP-B\venv\lib\site-packages\django\core\handlers\base.py", line 115, in _get_response
    response = self.process_exception_by_middleware(e, request)
  File "C:\Users\Sahil Arora\Desktop\SCP-B\venv\lib\site-packages\django\core\handlers\base.py", line 113, in _get_response
    response = wrapped_callback(request, *callback_args, **callback_kwargs)
  File "C:\Users\Sahil Arora\Desktop\SCP-B\venv\lib\site-packages\django\views\decorators\csrf.py", line 54, in wrapped_view
    return view_func(*args, **kwargs)
  File "C:\Users\Sahil Arora\Desktop\SCP-B\venv\lib\site-packages\django\views\generic\base.py", line 71, in view
    return self.dispatch(request, *args, **kwargs)
  File "C:\Users\Sahil Arora\Desktop\SCP-B\venv\lib\site-packages\rest_framework\views.py", line 505, in dispatch
    response = self.handle_exception(exc)
  File "C:\Users\Sahil Arora\Desktop\SCP-B\venv\lib\site-packages\rest_framework\views.py", line 465, in handle_exception
    self.raise_uncaught_exception(exc)
  File "C:\Users\Sahil Arora\Desktop\SCP-B\venv\lib\site-packages\rest_framework\views.py", line 476, in raise_uncaught_exception
    raise exc
  File "C:\Users\Sahil Arora\Desktop\SCP-B\venv\lib\site-packages\rest_framework\views.py", line 502, in dispatch
    response = handler(request, *args, **kwargs)
  File "C:\Users\Sahil Arora\Desktop\SCP-B\SCP-backened\SCPapp\views.py", line 46, in get
    emailVerifyData = emailVerify.objects.all()
NameError: name 'emailVerify' is not defined
2020-09-23 23:36:34,169 INFO     [autoreload.py:222] C:\Users\Sahil Arora\Desktop\SCP-B\SCP-backened\SCPapp\views.py changed, reloading.
2020-09-23 23:37:39,84 WARNING  [log.py:228] Not Found: /confirmEmailID/5547/
2020-09-23 23:38:45,756 INFO     [autoreload.py:222] C:\Users\Sahil Arora\Desktop\SCP-B\SCP-backened\SCP\urls.py changed, reloading.
2020-09-23 23:38:56,762 ERROR    [log.py:228] Internal Server Error: /confirmEmailID/5547/
Traceback (most recent call last):
  File "C:\Users\Sahil Arora\Desktop\SCP-B\venv\lib\site-packages\django\core\handlers\exception.py", line 34, in inner
    response = get_response(request)
  File "C:\Users\Sahil Arora\Desktop\SCP-B\venv\lib\site-packages\django\core\handlers\base.py", line 115, in _get_response
    response = self.process_exception_by_middleware(e, request)
  File "C:\Users\Sahil Arora\Desktop\SCP-B\venv\lib\site-packages\django\core\handlers\base.py", line 113, in _get_response
    response = wrapped_callback(request, *callback_args, **callback_kwargs)
  File "C:\Users\Sahil Arora\Desktop\SCP-B\venv\lib\site-packages\django\views\decorators\csrf.py", line 54, in wrapped_view
    return view_func(*args, **kwargs)
  File "C:\Users\Sahil Arora\Desktop\SCP-B\venv\lib\site-packages\django\views\generic\base.py", line 71, in view
    return self.dispatch(request, *args, **kwargs)
  File "C:\Users\Sahil Arora\Desktop\SCP-B\venv\lib\site-packages\rest_framework\views.py", line 505, in dispatch
    response = self.handle_exception(exc)
  File "C:\Users\Sahil Arora\Desktop\SCP-B\venv\lib\site-packages\rest_framework\views.py", line 465, in handle_exception
    self.raise_uncaught_exception(exc)
  File "C:\Users\Sahil Arora\Desktop\SCP-B\venv\lib\site-packages\rest_framework\views.py", line 476, in raise_uncaught_exception
    raise exc
  File "C:\Users\Sahil Arora\Desktop\SCP-B\venv\lib\site-packages\rest_framework\views.py", line 502, in dispatch
    response = handler(request, *args, **kwargs)
TypeError: get() got an unexpected keyword argument 'id'
2020-09-23 23:39:09,871 INFO     [autoreload.py:222] C:\Users\Sahil Arora\Desktop\SCP-B\SCP-backened\SCP\urls.py changed, reloading.
2020-09-23 23:39:22,79 WARNING  [log.py:228] Not Found: /confirmEmailID/5547/
2020-09-23 23:40:03,71 WARNING  [log.py:228] Not Found: /confirmEmailID/5547/
2020-09-23 23:40:58,622 INFO     [autoreload.py:222] C:\Users\Sahil Arora\Desktop\SCP-B\SCP-backened\SCPapp\views.py changed, reloading.
2020-09-23 23:41:52,238 INFO     [autoreload.py:222] C:\Users\Sahil Arora\Desktop\SCP-B\SCP-backened\SCPapp\admin.py changed, reloading.
2020-09-23 23:42:08,305 WARNING  [log.py:228] Not Found: /
2020-09-23 23:42:09,725 WARNING  [log.py:228] Not Found: /admin.
2020-09-23 23:44:36,812 ERROR    [log.py:228] Internal Server Error: /admin/SCPapp/emailverify/add/
Traceback (most recent call last):
  File "C:\Users\Sahil Arora\Desktop\SCP-B\venv\lib\site-packages\django\core\handlers\exception.py", line 34, in inner
    response = get_response(request)
  File "C:\Users\Sahil Arora\Desktop\SCP-B\venv\lib\site-packages\django\core\handlers\base.py", line 115, in _get_response
    response = self.process_exception_by_middleware(e, request)
  File "C:\Users\Sahil Arora\Desktop\SCP-B\venv\lib\site-packages\django\core\handlers\base.py", line 113, in _get_response
    response = wrapped_callback(request, *callback_args, **callback_kwargs)
  File "C:\Users\Sahil Arora\Desktop\SCP-B\venv\lib\site-packages\django\contrib\admin\options.py", line 607, in wrapper
    return self.admin_site.admin_view(view)(*args, **kwargs)
  File "C:\Users\Sahil Arora\Desktop\SCP-B\venv\lib\site-packages\django\utils\decorators.py", line 130, in _wrapped_view
    response = view_func(request, *args, **kwargs)
  File "C:\Users\Sahil Arora\Desktop\SCP-B\venv\lib\site-packages\django\views\decorators\cache.py", line 44, in _wrapped_view_func
    response = view_func(request, *args, **kwargs)
  File "C:\Users\Sahil Arora\Desktop\SCP-B\venv\lib\site-packages\django\contrib\admin\sites.py", line 231, in inner
    return view(request, *args, **kwargs)
  File "C:\Users\Sahil Arora\Desktop\SCP-B\venv\lib\site-packages\django\contrib\admin\options.py", line 1638, in add_view
    return self.changeform_view(request, None, form_url, extra_context)
  File "C:\Users\Sahil Arora\Desktop\SCP-B\venv\lib\site-packages\django\utils\decorators.py", line 43, in _wrapper
    return bound_method(*args, **kwargs)
  File "C:\Users\Sahil Arora\Desktop\SCP-B\venv\lib\site-packages\django\utils\decorators.py", line 130, in _wrapped_view
    response = view_func(request, *args, **kwargs)
  File "C:\Users\Sahil Arora\Desktop\SCP-B\venv\lib\site-packages\django\contrib\admin\options.py", line 1522, in changeform_view
    return self._changeform_view(request, object_id, form_url, extra_context)
  File "C:\Users\Sahil Arora\Desktop\SCP-B\venv\lib\site-packages\django\contrib\admin\options.py", line 1569, in _changeform_view
    self.log_addition(request, new_object, change_message)
  File "C:\Users\Sahil Arora\Desktop\SCP-B\venv\lib\site-packages\django\contrib\admin\options.py", line 807, in log_addition
    object_repr=str(object),
  File "C:\Users\Sahil Arora\Desktop\SCP-B\SCP-backened\SCPapp\models.py", line 52, in __str__
    return self.username
AttributeError: 'emailVerify' object has no attribute 'username'
2020-09-23 23:45:54,569 INFO     [autoreload.py:222] C:\Users\Sahil Arora\Desktop\SCP-B\SCP-backened\SCPapp\models.py changed, reloading.
2020-09-23 23:46:03,285 ERROR    [log.py:228] Internal Server Error: /admin/SCPapp/emailverify/add/
Traceback (most recent call last):
  File "C:\Users\Sahil Arora\Desktop\SCP-B\venv\lib\site-packages\django\core\handlers\exception.py", line 34, in inner
    response = get_response(request)
  File "C:\Users\Sahil Arora\Desktop\SCP-B\venv\lib\site-packages\django\core\handlers\base.py", line 115, in _get_response
    response = self.process_exception_by_middleware(e, request)
  File "C:\Users\Sahil Arora\Desktop\SCP-B\venv\lib\site-packages\django\core\handlers\base.py", line 113, in _get_response
    response = wrapped_callback(request, *callback_args, **callback_kwargs)
  File "C:\Users\Sahil Arora\Desktop\SCP-B\venv\lib\site-packages\django\contrib\admin\options.py", line 607, in wrapper
    return self.admin_site.admin_view(view)(*args, **kwargs)
  File "C:\Users\Sahil Arora\Desktop\SCP-B\venv\lib\site-packages\django\utils\decorators.py", line 130, in _wrapped_view
    response = view_func(request, *args, **kwargs)
  File "C:\Users\Sahil Arora\Desktop\SCP-B\venv\lib\site-packages\django\views\decorators\cache.py", line 44, in _wrapped_view_func
    response = view_func(request, *args, **kwargs)
  File "C:\Users\Sahil Arora\Desktop\SCP-B\venv\lib\site-packages\django\contrib\admin\sites.py", line 231, in inner
    return view(request, *args, **kwargs)
  File "C:\Users\Sahil Arora\Desktop\SCP-B\venv\lib\site-packages\django\contrib\admin\options.py", line 1638, in add_view
    return self.changeform_view(request, None, form_url, extra_context)
  File "C:\Users\Sahil Arora\Desktop\SCP-B\venv\lib\site-packages\django\utils\decorators.py", line 43, in _wrapper
    return bound_method(*args, **kwargs)
  File "C:\Users\Sahil Arora\Desktop\SCP-B\venv\lib\site-packages\django\utils\decorators.py", line 130, in _wrapped_view
    response = view_func(request, *args, **kwargs)
  File "C:\Users\Sahil Arora\Desktop\SCP-B\venv\lib\site-packages\django\contrib\admin\options.py", line 1522, in changeform_view
    return self._changeform_view(request, object_id, form_url, extra_context)
  File "C:\Users\Sahil Arora\Desktop\SCP-B\venv\lib\site-packages\django\contrib\admin\options.py", line 1569, in _changeform_view
    self.log_addition(request, new_object, change_message)
  File "C:\Users\Sahil Arora\Desktop\SCP-B\venv\lib\site-packages\django\contrib\admin\options.py", line 807, in log_addition
    object_repr=str(object),
TypeError: __str__ returned non-string (type int)
2020-09-23 23:46:21,9 INFO     [autoreload.py:222] C:\Users\Sahil Arora\Desktop\SCP-B\SCP-backened\SCPapp\models.py changed, reloading.
2020-09-23 23:46:59,239 ERROR    [log.py:228] Internal Server Error: /confirmEmailID/123/
Traceback (most recent call last):
  File "C:\Users\Sahil Arora\Desktop\SCP-B\venv\lib\site-packages\django\core\handlers\exception.py", line 34, in inner
    response = get_response(request)
  File "C:\Users\Sahil Arora\Desktop\SCP-B\venv\lib\site-packages\django\core\handlers\base.py", line 115, in _get_response
    response = self.process_exception_by_middleware(e, request)
  File "C:\Users\Sahil Arora\Desktop\SCP-B\venv\lib\site-packages\django\core\handlers\base.py", line 113, in _get_response
    response = wrapped_callback(request, *callback_args, **callback_kwargs)
  File "C:\Users\Sahil Arora\Desktop\SCP-B\venv\lib\site-packages\django\views\decorators\csrf.py", line 54, in wrapped_view
    return view_func(*args, **kwargs)
  File "C:\Users\Sahil Arora\Desktop\SCP-B\venv\lib\site-packages\django\views\generic\base.py", line 71, in view
    return self.dispatch(request, *args, **kwargs)
  File "C:\Users\Sahil Arora\Desktop\SCP-B\venv\lib\site-packages\rest_framework\views.py", line 505, in dispatch
    response = self.handle_exception(exc)
  File "C:\Users\Sahil Arora\Desktop\SCP-B\venv\lib\site-packages\rest_framework\views.py", line 465, in handle_exception
    self.raise_uncaught_exception(exc)
  File "C:\Users\Sahil Arora\Desktop\SCP-B\venv\lib\site-packages\rest_framework\views.py", line 476, in raise_uncaught_exception
    raise exc
  File "C:\Users\Sahil Arora\Desktop\SCP-B\venv\lib\site-packages\rest_framework\views.py", line 502, in dispatch
    response = handler(request, *args, **kwargs)
TypeError: get() got an unexpected keyword argument 'otp'
2020-09-23 23:48:51,65 INFO     [autoreload.py:222] C:\Users\Sahil Arora\Desktop\SCP-B\SCP-backened\SCPapp\views.py changed, reloading.
2020-09-23 23:49:16,549 ERROR    [log.py:228] Internal Server Error: /confirmEmailID/123/
Traceback (most recent call last):
  File "C:\Users\Sahil Arora\Desktop\SCP-B\venv\lib\site-packages\django\core\handlers\exception.py", line 34, in inner
    response = get_response(request)
  File "C:\Users\Sahil Arora\Desktop\SCP-B\venv\lib\site-packages\django\core\handlers\base.py", line 115, in _get_response
    response = self.process_exception_by_middleware(e, request)
  File "C:\Users\Sahil Arora\Desktop\SCP-B\venv\lib\site-packages\django\core\handlers\base.py", line 113, in _get_response
    response = wrapped_callback(request, *callback_args, **callback_kwargs)
  File "C:\Users\Sahil Arora\Desktop\SCP-B\venv\lib\site-packages\django\views\decorators\csrf.py", line 54, in wrapped_view
    return view_func(*args, **kwargs)
  File "C:\Users\Sahil Arora\Desktop\SCP-B\venv\lib\site-packages\django\views\generic\base.py", line 71, in view
    return self.dispatch(request, *args, **kwargs)
  File "C:\Users\Sahil Arora\Desktop\SCP-B\venv\lib\site-packages\rest_framework\views.py", line 505, in dispatch
    response = self.handle_exception(exc)
  File "C:\Users\Sahil Arora\Desktop\SCP-B\venv\lib\site-packages\rest_framework\views.py", line 465, in handle_exception
    self.raise_uncaught_exception(exc)
  File "C:\Users\Sahil Arora\Desktop\SCP-B\venv\lib\site-packages\rest_framework\views.py", line 476, in raise_uncaught_exception
    raise exc
  File "C:\Users\Sahil Arora\Desktop\SCP-B\venv\lib\site-packages\rest_framework\views.py", line 502, in dispatch
    response = handler(request, *args, **kwargs)
TypeError: get() got an unexpected keyword argument 'otp'
2020-09-23 23:50:13,241 ERROR    [log.py:228] Internal Server Error: /confirmEmailID/123/
Traceback (most recent call last):
  File "C:\Users\Sahil Arora\Desktop\SCP-B\venv\lib\site-packages\django\core\handlers\exception.py", line 34, in inner
    response = get_response(request)
  File "C:\Users\Sahil Arora\Desktop\SCP-B\venv\lib\site-packages\django\core\handlers\base.py", line 115, in _get_response
    response = self.process_exception_by_middleware(e, request)
  File "C:\Users\Sahil Arora\Desktop\SCP-B\venv\lib\site-packages\django\core\handlers\base.py", line 113, in _get_response
    response = wrapped_callback(request, *callback_args, **callback_kwargs)
  File "C:\Users\Sahil Arora\Desktop\SCP-B\venv\lib\site-packages\django\views\decorators\csrf.py", line 54, in wrapped_view
    return view_func(*args, **kwargs)
  File "C:\Users\Sahil Arora\Desktop\SCP-B\venv\lib\site-packages\django\views\generic\base.py", line 71, in view
    return self.dispatch(request, *args, **kwargs)
  File "C:\Users\Sahil Arora\Desktop\SCP-B\venv\lib\site-packages\rest_framework\views.py", line 505, in dispatch
    response = self.handle_exception(exc)
  File "C:\Users\Sahil Arora\Desktop\SCP-B\venv\lib\site-packages\rest_framework\views.py", line 465, in handle_exception
    self.raise_uncaught_exception(exc)
  File "C:\Users\Sahil Arora\Desktop\SCP-B\venv\lib\site-packages\rest_framework\views.py", line 476, in raise_uncaught_exception
    raise exc
  File "C:\Users\Sahil Arora\Desktop\SCP-B\venv\lib\site-packages\rest_framework\views.py", line 502, in dispatch
    response = handler(request, *args, **kwargs)
TypeError: get() got an unexpected keyword argument 'otp'
2020-09-23 23:50:39,468 INFO     [autoreload.py:222] C:\Users\Sahil Arora\Desktop\SCP-B\SCP-backened\SCP\urls.py changed, reloading.
2020-09-23 23:53:04,99 INFO     [autoreload.py:222] C:\Users\Sahil Arora\Desktop\SCP-B\SCP-backened\SCPapp\views.py changed, reloading.
2020-09-23 23:53:41,553 ERROR    [log.py:228] Internal Server Error: /confirmEmailID/
Traceback (most recent call last):
  File "C:\Users\Sahil Arora\Desktop\SCP-B\venv\lib\site-packages\django\core\handlers\exception.py", line 34, in inner
    response = get_response(request)
  File "C:\Users\Sahil Arora\Desktop\SCP-B\venv\lib\site-packages\django\core\handlers\base.py", line 115, in _get_response
    response = self.process_exception_by_middleware(e, request)
  File "C:\Users\Sahil Arora\Desktop\SCP-B\venv\lib\site-packages\django\core\handlers\base.py", line 113, in _get_response
    response = wrapped_callback(request, *callback_args, **callback_kwargs)
  File "C:\Users\Sahil Arora\Desktop\SCP-B\venv\lib\site-packages\django\views\decorators\csrf.py", line 54, in wrapped_view
    return view_func(*args, **kwargs)
  File "C:\Users\Sahil Arora\Desktop\SCP-B\venv\lib\site-packages\django\views\generic\base.py", line 71, in view
    return self.dispatch(request, *args, **kwargs)
  File "C:\Users\Sahil Arora\Desktop\SCP-B\venv\lib\site-packages\rest_framework\views.py", line 505, in dispatch
    response = self.handle_exception(exc)
  File "C:\Users\Sahil Arora\Desktop\SCP-B\venv\lib\site-packages\rest_framework\views.py", line 465, in handle_exception
    self.raise_uncaught_exception(exc)
  File "C:\Users\Sahil Arora\Desktop\SCP-B\venv\lib\site-packages\rest_framework\views.py", line 476, in raise_uncaught_exception
    raise exc
  File "C:\Users\Sahil Arora\Desktop\SCP-B\venv\lib\site-packages\rest_framework\views.py", line 502, in dispatch
    response = handler(request, *args, **kwargs)
  File "C:\Users\Sahil Arora\Desktop\SCP-B\SCP-backened\SCPapp\views.py", line 39, in post
    [request.data["Email"]], fail_silently=False, )
KeyError: 'Email'
2020-09-23 23:54:35,623 INFO     [autoreload.py:222] C:\Users\Sahil Arora\Desktop\SCP-B\SCP-backened\SCPapp\views.py changed, reloading.
2020-09-23 23:54:49,368 ERROR    [log.py:228] Internal Server Error: /confirmEmailID/
Traceback (most recent call last):
  File "C:\Users\Sahil Arora\Desktop\SCP-B\venv\lib\site-packages\django\core\handlers\exception.py", line 34, in inner
    response = get_response(request)
  File "C:\Users\Sahil Arora\Desktop\SCP-B\venv\lib\site-packages\django\core\handlers\base.py", line 115, in _get_response
    response = self.process_exception_by_middleware(e, request)
  File "C:\Users\Sahil Arora\Desktop\SCP-B\venv\lib\site-packages\django\core\handlers\base.py", line 113, in _get_response
    response = wrapped_callback(request, *callback_args, **callback_kwargs)
  File "C:\Users\Sahil Arora\Desktop\SCP-B\venv\lib\site-packages\django\views\decorators\csrf.py", line 54, in wrapped_view
    return view_func(*args, **kwargs)
  File "C:\Users\Sahil Arora\Desktop\SCP-B\venv\lib\site-packages\django\views\generic\base.py", line 71, in view
    return self.dispatch(request, *args, **kwargs)
  File "C:\Users\Sahil Arora\Desktop\SCP-B\venv\lib\site-packages\rest_framework\views.py", line 505, in dispatch
    response = self.handle_exception(exc)
  File "C:\Users\Sahil Arora\Desktop\SCP-B\venv\lib\site-packages\rest_framework\views.py", line 465, in handle_exception
    self.raise_uncaught_exception(exc)
  File "C:\Users\Sahil Arora\Desktop\SCP-B\venv\lib\site-packages\rest_framework\views.py", line 476, in raise_uncaught_exception
    raise exc
  File "C:\Users\Sahil Arora\Desktop\SCP-B\venv\lib\site-packages\rest_framework\views.py", line 502, in dispatch
    response = handler(request, *args, **kwargs)
  File "C:\Users\Sahil Arora\Desktop\SCP-B\SCP-backened\SCPapp\views.py", line 39, in post
    [request.data["EmailId"]], fail_silently=False, )
KeyError: 'EmailId'
2020-09-23 23:55:08,220 ERROR    [log.py:228] Internal Server Error: /confirmEmailID/
Traceback (most recent call last):
  File "C:\Users\Sahil Arora\Desktop\SCP-B\venv\lib\site-packages\django\core\handlers\exception.py", line 34, in inner
    response = get_response(request)
  File "C:\Users\Sahil Arora\Desktop\SCP-B\venv\lib\site-packages\django\core\handlers\base.py", line 115, in _get_response
    response = self.process_exception_by_middleware(e, request)
  File "C:\Users\Sahil Arora\Desktop\SCP-B\venv\lib\site-packages\django\core\handlers\base.py", line 113, in _get_response
    response = wrapped_callback(request, *callback_args, **callback_kwargs)
  File "C:\Users\Sahil Arora\Desktop\SCP-B\venv\lib\site-packages\django\views\decorators\csrf.py", line 54, in wrapped_view
    return view_func(*args, **kwargs)
  File "C:\Users\Sahil Arora\Desktop\SCP-B\venv\lib\site-packages\django\views\generic\base.py", line 71, in view
    return self.dispatch(request, *args, **kwargs)
  File "C:\Users\Sahil Arora\Desktop\SCP-B\venv\lib\site-packages\rest_framework\views.py", line 505, in dispatch
    response = self.handle_exception(exc)
  File "C:\Users\Sahil Arora\Desktop\SCP-B\venv\lib\site-packages\rest_framework\views.py", line 465, in handle_exception
    self.raise_uncaught_exception(exc)
  File "C:\Users\Sahil Arora\Desktop\SCP-B\venv\lib\site-packages\rest_framework\views.py", line 476, in raise_uncaught_exception
    raise exc
  File "C:\Users\Sahil Arora\Desktop\SCP-B\venv\lib\site-packages\rest_framework\views.py", line 502, in dispatch
    response = handler(request, *args, **kwargs)
  File "C:\Users\Sahil Arora\Desktop\SCP-B\SCP-backened\SCPapp\views.py", line 44, in post
    return Response(login_serializer.errors, status=status.HTTP_400_BAD_REQUEST)
NameError: name 'login_serializer' is not defined
2020-09-23 23:55:30,262 INFO     [autoreload.py:222] C:\Users\Sahil Arora\Desktop\SCP-B\SCP-backened\SCPapp\views.py changed, reloading.
2020-09-23 23:55:47,553 ERROR    [log.py:228] Internal Server Error: /confirmEmailID/
Traceback (most recent call last):
  File "C:\Users\Sahil Arora\Desktop\SCP-B\venv\lib\site-packages\django\core\handlers\exception.py", line 34, in inner
    response = get_response(request)
  File "C:\Users\Sahil Arora\Desktop\SCP-B\venv\lib\site-packages\django\core\handlers\base.py", line 145, in _get_response
    response = self.process_exception_by_middleware(e, request)
  File "C:\Users\Sahil Arora\Desktop\SCP-B\venv\lib\site-packages\django\core\handlers\base.py", line 143, in _get_response
    response = response.render()
  File "C:\Users\Sahil Arora\Desktop\SCP-B\venv\lib\site-packages\django\template\response.py", line 105, in render
    self.content = self.rendered_content
  File "C:\Users\Sahil Arora\Desktop\SCP-B\venv\lib\site-packages\rest_framework\response.py", line 70, in rendered_content
    ret = renderer.render(self.data, accepted_media_type, context)
  File "C:\Users\Sahil Arora\Desktop\SCP-B\venv\lib\site-packages\rest_framework\renderers.py", line 103, in render
    allow_nan=not self.strict, separators=separators
  File "C:\Users\Sahil Arora\Desktop\SCP-B\venv\lib\site-packages\rest_framework\utils\json.py", line 25, in dumps
    return json.dumps(*args, **kwargs)
  File "C:\Users\Sahil Arora\AppData\Local\Programs\Python\Python36\lib\json\__init__.py", line 238, in dumps
    **kw).encode(obj)
  File "C:\Users\Sahil Arora\AppData\Local\Programs\Python\Python36\lib\json\encoder.py", line 199, in encode
    chunks = self.iterencode(o, _one_shot=True)
  File "C:\Users\Sahil Arora\AppData\Local\Programs\Python\Python36\lib\json\encoder.py", line 257, in iterencode
    return _iterencode(o, 0)
  File "C:\Users\Sahil Arora\Desktop\SCP-B\venv\lib\site-packages\rest_framework\utils\encoders.py", line 67, in default
    return super().default(obj)
  File "C:\Users\Sahil Arora\AppData\Local\Programs\Python\Python36\lib\json\encoder.py", line 180, in default
    o.__class__.__name__)
TypeError: Object of type 'property' is not JSON serializable
2020-09-23 23:57:11,3 INFO     [autoreload.py:222] C:\Users\Sahil Arora\Desktop\SCP-B\SCP-backened\SCPapp\views.py changed, reloading.
2020-09-23 23:59:11,305 ERROR    [log.py:228] Internal Server Error: /confirmEmailID/
Traceback (most recent call last):
  File "C:\Users\Sahil Arora\Desktop\SCP-B\venv\lib\site-packages\django\core\handlers\exception.py", line 34, in inner
    response = get_response(request)
  File "C:\Users\Sahil Arora\Desktop\SCP-B\venv\lib\site-packages\django\core\handlers\base.py", line 145, in _get_response
    response = self.process_exception_by_middleware(e, request)
  File "C:\Users\Sahil Arora\Desktop\SCP-B\venv\lib\site-packages\django\core\handlers\base.py", line 143, in _get_response
    response = response.render()
  File "C:\Users\Sahil Arora\Desktop\SCP-B\venv\lib\site-packages\django\template\response.py", line 105, in render
    self.content = self.rendered_content
  File "C:\Users\Sahil Arora\Desktop\SCP-B\venv\lib\site-packages\rest_framework\response.py", line 70, in rendered_content
    ret = renderer.render(self.data, accepted_media_type, context)
  File "C:\Users\Sahil Arora\Desktop\SCP-B\venv\lib\site-packages\rest_framework\renderers.py", line 103, in render
    allow_nan=not self.strict, separators=separators
  File "C:\Users\Sahil Arora\Desktop\SCP-B\venv\lib\site-packages\rest_framework\utils\json.py", line 25, in dumps
    return json.dumps(*args, **kwargs)
  File "C:\Users\Sahil Arora\AppData\Local\Programs\Python\Python36\lib\json\__init__.py", line 238, in dumps
    **kw).encode(obj)
  File "C:\Users\Sahil Arora\AppData\Local\Programs\Python\Python36\lib\json\encoder.py", line 199, in encode
    chunks = self.iterencode(o, _one_shot=True)
  File "C:\Users\Sahil Arora\AppData\Local\Programs\Python\Python36\lib\json\encoder.py", line 257, in iterencode
    return _iterencode(o, 0)
  File "C:\Users\Sahil Arora\Desktop\SCP-B\venv\lib\site-packages\rest_framework\utils\encoders.py", line 67, in default
    return super().default(obj)
  File "C:\Users\Sahil Arora\AppData\Local\Programs\Python\Python36\lib\json\encoder.py", line 180, in default
    o.__class__.__name__)
TypeError: Object of type 'property' is not JSON serializable
2020-09-23 23:59:34,193 INFO     [autoreload.py:222] C:\Users\Sahil Arora\Desktop\SCP-B\SCP-backened\SCPapp\views.py changed, reloading.
2020-09-23 23:59:47,527 ERROR    [log.py:228] Internal Server Error: /confirmEmailID/
Traceback (most recent call last):
  File "C:\Users\Sahil Arora\Desktop\SCP-B\venv\lib\site-packages\django\core\handlers\exception.py", line 34, in inner
    response = get_response(request)
  File "C:\Users\Sahil Arora\Desktop\SCP-B\venv\lib\site-packages\django\core\handlers\base.py", line 145, in _get_response
    response = self.process_exception_by_middleware(e, request)
  File "C:\Users\Sahil Arora\Desktop\SCP-B\venv\lib\site-packages\django\core\handlers\base.py", line 143, in _get_response
    response = response.render()
  File "C:\Users\Sahil Arora\Desktop\SCP-B\venv\lib\site-packages\django\template\response.py", line 105, in render
    self.content = self.rendered_content
  File "C:\Users\Sahil Arora\Desktop\SCP-B\venv\lib\site-packages\rest_framework\response.py", line 70, in rendered_content
    ret = renderer.render(self.data, accepted_media_type, context)
  File "C:\Users\Sahil Arora\Desktop\SCP-B\venv\lib\site-packages\rest_framework\renderers.py", line 103, in render
    allow_nan=not self.strict, separators=separators
  File "C:\Users\Sahil Arora\Desktop\SCP-B\venv\lib\site-packages\rest_framework\utils\json.py", line 25, in dumps
    return json.dumps(*args, **kwargs)
  File "C:\Users\Sahil Arora\AppData\Local\Programs\Python\Python36\lib\json\__init__.py", line 238, in dumps
    **kw).encode(obj)
  File "C:\Users\Sahil Arora\AppData\Local\Programs\Python\Python36\lib\json\encoder.py", line 199, in encode
    chunks = self.iterencode(o, _one_shot=True)
  File "C:\Users\Sahil Arora\AppData\Local\Programs\Python\Python36\lib\json\encoder.py", line 257, in iterencode
    return _iterencode(o, 0)
  File "C:\Users\Sahil Arora\Desktop\SCP-B\venv\lib\site-packages\rest_framework\utils\encoders.py", line 67, in default
    return super().default(obj)
  File "C:\Users\Sahil Arora\AppData\Local\Programs\Python\Python36\lib\json\encoder.py", line 180, in default
    o.__class__.__name__)
TypeError: Object of type 'property' is not JSON serializable
2020-09-24 00:00:38,819 INFO     [autoreload.py:222] C:\Users\Sahil Arora\Desktop\SCP-B\SCP-backened\SCPapp\views.py changed, reloading.
2020-09-24 00:00:58,699 ERROR    [log.py:228] Internal Server Error: /confirmEmailID/
Traceback (most recent call last):
  File "C:\Users\Sahil Arora\Desktop\SCP-B\venv\lib\site-packages\django\core\handlers\exception.py", line 34, in inner
    response = get_response(request)
  File "C:\Users\Sahil Arora\Desktop\SCP-B\venv\lib\site-packages\django\core\handlers\base.py", line 145, in _get_response
    response = self.process_exception_by_middleware(e, request)
  File "C:\Users\Sahil Arora\Desktop\SCP-B\venv\lib\site-packages\django\core\handlers\base.py", line 143, in _get_response
    response = response.render()
  File "C:\Users\Sahil Arora\Desktop\SCP-B\venv\lib\site-packages\django\template\response.py", line 105, in render
    self.content = self.rendered_content
  File "C:\Users\Sahil Arora\Desktop\SCP-B\venv\lib\site-packages\rest_framework\response.py", line 70, in rendered_content
    ret = renderer.render(self.data, accepted_media_type, context)
  File "C:\Users\Sahil Arora\Desktop\SCP-B\venv\lib\site-packages\rest_framework\renderers.py", line 103, in render
    allow_nan=not self.strict, separators=separators
  File "C:\Users\Sahil Arora\Desktop\SCP-B\venv\lib\site-packages\rest_framework\utils\json.py", line 25, in dumps
    return json.dumps(*args, **kwargs)
  File "C:\Users\Sahil Arora\AppData\Local\Programs\Python\Python36\lib\json\__init__.py", line 238, in dumps
    **kw).encode(obj)
  File "C:\Users\Sahil Arora\AppData\Local\Programs\Python\Python36\lib\json\encoder.py", line 199, in encode
    chunks = self.iterencode(o, _one_shot=True)
  File "C:\Users\Sahil Arora\AppData\Local\Programs\Python\Python36\lib\json\encoder.py", line 257, in iterencode
    return _iterencode(o, 0)
  File "C:\Users\Sahil Arora\Desktop\SCP-B\venv\lib\site-packages\rest_framework\utils\encoders.py", line 67, in default
    return super().default(obj)
  File "C:\Users\Sahil Arora\AppData\Local\Programs\Python\Python36\lib\json\encoder.py", line 180, in default
    o.__class__.__name__)
TypeError: Object of type 'property' is not JSON serializable
2020-09-24 00:01:31,880 INFO     [autoreload.py:222] C:\Users\Sahil Arora\Desktop\SCP-B\SCP-backened\SCPapp\views.py changed, reloading.
2020-09-24 00:01:44,636 ERROR    [log.py:228] Internal Server Error: /confirmEmailID/
Traceback (most recent call last):
  File "C:\Users\Sahil Arora\Desktop\SCP-B\venv\lib\site-packages\django\core\handlers\exception.py", line 34, in inner
    response = get_response(request)
  File "C:\Users\Sahil Arora\Desktop\SCP-B\venv\lib\site-packages\django\core\handlers\base.py", line 145, in _get_response
    response = self.process_exception_by_middleware(e, request)
  File "C:\Users\Sahil Arora\Desktop\SCP-B\venv\lib\site-packages\django\core\handlers\base.py", line 143, in _get_response
    response = response.render()
  File "C:\Users\Sahil Arora\Desktop\SCP-B\venv\lib\site-packages\django\template\response.py", line 105, in render
    self.content = self.rendered_content
  File "C:\Users\Sahil Arora\Desktop\SCP-B\venv\lib\site-packages\rest_framework\response.py", line 70, in rendered_content
    ret = renderer.render(self.data, accepted_media_type, context)
  File "C:\Users\Sahil Arora\Desktop\SCP-B\venv\lib\site-packages\rest_framework\renderers.py", line 103, in render
    allow_nan=not self.strict, separators=separators
  File "C:\Users\Sahil Arora\Desktop\SCP-B\venv\lib\site-packages\rest_framework\utils\json.py", line 25, in dumps
    return json.dumps(*args, **kwargs)
  File "C:\Users\Sahil Arora\AppData\Local\Programs\Python\Python36\lib\json\__init__.py", line 238, in dumps
    **kw).encode(obj)
  File "C:\Users\Sahil Arora\AppData\Local\Programs\Python\Python36\lib\json\encoder.py", line 199, in encode
    chunks = self.iterencode(o, _one_shot=True)
  File "C:\Users\Sahil Arora\AppData\Local\Programs\Python\Python36\lib\json\encoder.py", line 257, in iterencode
    return _iterencode(o, 0)
  File "C:\Users\Sahil Arora\Desktop\SCP-B\venv\lib\site-packages\rest_framework\utils\encoders.py", line 67, in default
    return super().default(obj)
  File "C:\Users\Sahil Arora\AppData\Local\Programs\Python\Python36\lib\json\encoder.py", line 180, in default
    o.__class__.__name__)
TypeError: Object of type 'property' is not JSON serializable
2020-09-24 00:02:35,890 INFO     [autoreload.py:222] C:\Users\Sahil Arora\Desktop\SCP-B\SCP-backened\SCPapp\views.py changed, reloading.
2020-09-24 00:02:49,171 ERROR    [log.py:228] Internal Server Error: /confirmEmailID/
Traceback (most recent call last):
  File "C:\Users\Sahil Arora\Desktop\SCP-B\venv\lib\site-packages\django\core\handlers\exception.py", line 34, in inner
    response = get_response(request)
  File "C:\Users\Sahil Arora\Desktop\SCP-B\venv\lib\site-packages\django\core\handlers\base.py", line 145, in _get_response
    response = self.process_exception_by_middleware(e, request)
  File "C:\Users\Sahil Arora\Desktop\SCP-B\venv\lib\site-packages\django\core\handlers\base.py", line 143, in _get_response
    response = response.render()
  File "C:\Users\Sahil Arora\Desktop\SCP-B\venv\lib\site-packages\django\template\response.py", line 105, in render
    self.content = self.rendered_content
  File "C:\Users\Sahil Arora\Desktop\SCP-B\venv\lib\site-packages\rest_framework\response.py", line 70, in rendered_content
    ret = renderer.render(self.data, accepted_media_type, context)
  File "C:\Users\Sahil Arora\Desktop\SCP-B\venv\lib\site-packages\rest_framework\renderers.py", line 103, in render
    allow_nan=not self.strict, separators=separators
  File "C:\Users\Sahil Arora\Desktop\SCP-B\venv\lib\site-packages\rest_framework\utils\json.py", line 25, in dumps
    return json.dumps(*args, **kwargs)
  File "C:\Users\Sahil Arora\AppData\Local\Programs\Python\Python36\lib\json\__init__.py", line 238, in dumps
    **kw).encode(obj)
  File "C:\Users\Sahil Arora\AppData\Local\Programs\Python\Python36\lib\json\encoder.py", line 199, in encode
    chunks = self.iterencode(o, _one_shot=True)
  File "C:\Users\Sahil Arora\AppData\Local\Programs\Python\Python36\lib\json\encoder.py", line 257, in iterencode
    return _iterencode(o, 0)
  File "C:\Users\Sahil Arora\Desktop\SCP-B\venv\lib\site-packages\rest_framework\utils\encoders.py", line 67, in default
    return super().default(obj)
  File "C:\Users\Sahil Arora\AppData\Local\Programs\Python\Python36\lib\json\encoder.py", line 180, in default
    o.__class__.__name__)
TypeError: Object of type 'property' is not JSON serializable
2020-09-24 00:03:22,809 INFO     [autoreload.py:222] C:\Users\Sahil Arora\Desktop\SCP-B\SCP-backened\SCPapp\views.py changed, reloading.
2020-09-24 00:03:32,889 ERROR    [log.py:228] Internal Server Error: /confirmEmailID/
Traceback (most recent call last):
  File "C:\Users\Sahil Arora\Desktop\SCP-B\venv\lib\site-packages\django\core\handlers\exception.py", line 34, in inner
    response = get_response(request)
  File "C:\Users\Sahil Arora\Desktop\SCP-B\venv\lib\site-packages\django\core\handlers\base.py", line 145, in _get_response
    response = self.process_exception_by_middleware(e, request)
  File "C:\Users\Sahil Arora\Desktop\SCP-B\venv\lib\site-packages\django\core\handlers\base.py", line 143, in _get_response
    response = response.render()
  File "C:\Users\Sahil Arora\Desktop\SCP-B\venv\lib\site-packages\django\template\response.py", line 105, in render
    self.content = self.rendered_content
  File "C:\Users\Sahil Arora\Desktop\SCP-B\venv\lib\site-packages\rest_framework\response.py", line 70, in rendered_content
    ret = renderer.render(self.data, accepted_media_type, context)
  File "C:\Users\Sahil Arora\Desktop\SCP-B\venv\lib\site-packages\rest_framework\renderers.py", line 103, in render
    allow_nan=not self.strict, separators=separators
  File "C:\Users\Sahil Arora\Desktop\SCP-B\venv\lib\site-packages\rest_framework\utils\json.py", line 25, in dumps
    return json.dumps(*args, **kwargs)
  File "C:\Users\Sahil Arora\AppData\Local\Programs\Python\Python36\lib\json\__init__.py", line 238, in dumps
    **kw).encode(obj)
  File "C:\Users\Sahil Arora\AppData\Local\Programs\Python\Python36\lib\json\encoder.py", line 199, in encode
    chunks = self.iterencode(o, _one_shot=True)
  File "C:\Users\Sahil Arora\AppData\Local\Programs\Python\Python36\lib\json\encoder.py", line 257, in iterencode
    return _iterencode(o, 0)
  File "C:\Users\Sahil Arora\Desktop\SCP-B\venv\lib\site-packages\rest_framework\utils\encoders.py", line 67, in default
    return super().default(obj)
  File "C:\Users\Sahil Arora\AppData\Local\Programs\Python\Python36\lib\json\encoder.py", line 180, in default
    o.__class__.__name__)
TypeError: Object of type 'property' is not JSON serializable
2020-09-24 00:03:52,29 INFO     [autoreload.py:222] C:\Users\Sahil Arora\Desktop\SCP-B\SCP-backened\SCPapp\views.py changed, reloading.
2020-09-24 00:04:05,747 ERROR    [log.py:228] Internal Server Error: /confirmEmailID/
Traceback (most recent call last):
  File "C:\Users\Sahil Arora\Desktop\SCP-B\venv\lib\site-packages\django\core\handlers\exception.py", line 34, in inner
    response = get_response(request)
  File "C:\Users\Sahil Arora\Desktop\SCP-B\venv\lib\site-packages\django\core\handlers\base.py", line 145, in _get_response
    response = self.process_exception_by_middleware(e, request)
  File "C:\Users\Sahil Arora\Desktop\SCP-B\venv\lib\site-packages\django\core\handlers\base.py", line 143, in _get_response
    response = response.render()
  File "C:\Users\Sahil Arora\Desktop\SCP-B\venv\lib\site-packages\django\template\response.py", line 105, in render
    self.content = self.rendered_content
  File "C:\Users\Sahil Arora\Desktop\SCP-B\venv\lib\site-packages\rest_framework\response.py", line 70, in rendered_content
    ret = renderer.render(self.data, accepted_media_type, context)
  File "C:\Users\Sahil Arora\Desktop\SCP-B\venv\lib\site-packages\rest_framework\renderers.py", line 103, in render
    allow_nan=not self.strict, separators=separators
  File "C:\Users\Sahil Arora\Desktop\SCP-B\venv\lib\site-packages\rest_framework\utils\json.py", line 25, in dumps
    return json.dumps(*args, **kwargs)
  File "C:\Users\Sahil Arora\AppData\Local\Programs\Python\Python36\lib\json\__init__.py", line 238, in dumps
    **kw).encode(obj)
  File "C:\Users\Sahil Arora\AppData\Local\Programs\Python\Python36\lib\json\encoder.py", line 199, in encode
    chunks = self.iterencode(o, _one_shot=True)
  File "C:\Users\Sahil Arora\AppData\Local\Programs\Python\Python36\lib\json\encoder.py", line 257, in iterencode
    return _iterencode(o, 0)
  File "C:\Users\Sahil Arora\Desktop\SCP-B\venv\lib\site-packages\rest_framework\utils\encoders.py", line 67, in default
    return super().default(obj)
  File "C:\Users\Sahil Arora\AppData\Local\Programs\Python\Python36\lib\json\encoder.py", line 180, in default
    o.__class__.__name__)
TypeError: Object of type 'property' is not JSON serializable
2020-09-24 00:04:35,493 INFO     [autoreload.py:222] C:\Users\Sahil Arora\Desktop\SCP-B\SCP-backened\SCPapp\views.py changed, reloading.
2020-09-24 00:04:46,697 ERROR    [log.py:228] Internal Server Error: /confirmEmailID/
Traceback (most recent call last):
  File "C:\Users\Sahil Arora\Desktop\SCP-B\venv\lib\site-packages\django\core\handlers\exception.py", line 34, in inner
    response = get_response(request)
  File "C:\Users\Sahil Arora\Desktop\SCP-B\venv\lib\site-packages\django\core\handlers\base.py", line 145, in _get_response
    response = self.process_exception_by_middleware(e, request)
  File "C:\Users\Sahil Arora\Desktop\SCP-B\venv\lib\site-packages\django\core\handlers\base.py", line 143, in _get_response
    response = response.render()
  File "C:\Users\Sahil Arora\Desktop\SCP-B\venv\lib\site-packages\django\template\response.py", line 105, in render
    self.content = self.rendered_content
  File "C:\Users\Sahil Arora\Desktop\SCP-B\venv\lib\site-packages\rest_framework\response.py", line 70, in rendered_content
    ret = renderer.render(self.data, accepted_media_type, context)
  File "C:\Users\Sahil Arora\Desktop\SCP-B\venv\lib\site-packages\rest_framework\renderers.py", line 103, in render
    allow_nan=not self.strict, separators=separators
  File "C:\Users\Sahil Arora\Desktop\SCP-B\venv\lib\site-packages\rest_framework\utils\json.py", line 25, in dumps
    return json.dumps(*args, **kwargs)
  File "C:\Users\Sahil Arora\AppData\Local\Programs\Python\Python36\lib\json\__init__.py", line 238, in dumps
    **kw).encode(obj)
  File "C:\Users\Sahil Arora\AppData\Local\Programs\Python\Python36\lib\json\encoder.py", line 199, in encode
    chunks = self.iterencode(o, _one_shot=True)
  File "C:\Users\Sahil Arora\AppData\Local\Programs\Python\Python36\lib\json\encoder.py", line 257, in iterencode
    return _iterencode(o, 0)
  File "C:\Users\Sahil Arora\Desktop\SCP-B\venv\lib\site-packages\rest_framework\utils\encoders.py", line 67, in default
    return super().default(obj)
  File "C:\Users\Sahil Arora\AppData\Local\Programs\Python\Python36\lib\json\encoder.py", line 180, in default
    o.__class__.__name__)
TypeError: Object of type 'property' is not JSON serializable
2020-09-24 00:06:56,685 INFO     [autoreload.py:222] C:\Users\Sahil Arora\Desktop\SCP-B\SCP-backened\SCPapp\views.py changed, reloading.
2020-09-24 00:08:04,446 INFO     [autoreload.py:222] C:\Users\Sahil Arora\Desktop\SCP-B\SCP-backened\SCPapp\views.py changed, reloading.
2020-09-24 00:08:48,1 ERROR    [log.py:228] Internal Server Error: /confirmEmailID/6514/
Traceback (most recent call last):
  File "C:\Users\Sahil Arora\Desktop\SCP-B\venv\lib\site-packages\django\core\handlers\exception.py", line 34, in inner
    response = get_response(request)
  File "C:\Users\Sahil Arora\Desktop\SCP-B\venv\lib\site-packages\django\core\handlers\base.py", line 115, in _get_response
    response = self.process_exception_by_middleware(e, request)
  File "C:\Users\Sahil Arora\Desktop\SCP-B\venv\lib\site-packages\django\core\handlers\base.py", line 113, in _get_response
    response = wrapped_callback(request, *callback_args, **callback_kwargs)
  File "C:\Users\Sahil Arora\Desktop\SCP-B\venv\lib\site-packages\django\views\decorators\csrf.py", line 54, in wrapped_view
    return view_func(*args, **kwargs)
  File "C:\Users\Sahil Arora\Desktop\SCP-B\venv\lib\site-packages\django\views\generic\base.py", line 71, in view
    return self.dispatch(request, *args, **kwargs)
  File "C:\Users\Sahil Arora\Desktop\SCP-B\venv\lib\site-packages\rest_framework\views.py", line 505, in dispatch
    response = self.handle_exception(exc)
  File "C:\Users\Sahil Arora\Desktop\SCP-B\venv\lib\site-packages\rest_framework\views.py", line 465, in handle_exception
    self.raise_uncaught_exception(exc)
  File "C:\Users\Sahil Arora\Desktop\SCP-B\venv\lib\site-packages\rest_framework\views.py", line 476, in raise_uncaught_exception
    raise exc
  File "C:\Users\Sahil Arora\Desktop\SCP-B\venv\lib\site-packages\rest_framework\views.py", line 502, in dispatch
    response = handler(request, *args, **kwargs)
TypeError: get() got an unexpected keyword argument 'otp'
2020-09-24 00:10:04,112 INFO     [autoreload.py:222] C:\Users\Sahil Arora\Desktop\SCP-B\SCP-backened\SCPapp\views.py changed, reloading.
2020-09-24 00:10:52,486 INFO     [autoreload.py:222] C:\Users\Sahil Arora\Desktop\SCP-B\SCP-backened\SCPapp\models.py changed, reloading.
2020-09-24 00:12:30,764 INFO     [autoreload.py:222] C:\Users\Sahil Arora\Desktop\SCP-B\SCP-backened\SCPapp\views.py changed, reloading.
2020-09-24 00:12:41,742 ERROR    [log.py:228] Internal Server Error: /confirmEmailID/6514/
Traceback (most recent call last):
  File "C:\Users\Sahil Arora\Desktop\SCP-B\venv\lib\site-packages\django\core\handlers\exception.py", line 34, in inner
    response = get_response(request)
  File "C:\Users\Sahil Arora\Desktop\SCP-B\venv\lib\site-packages\django\core\handlers\base.py", line 115, in _get_response
    response = self.process_exception_by_middleware(e, request)
  File "C:\Users\Sahil Arora\Desktop\SCP-B\venv\lib\site-packages\django\core\handlers\base.py", line 113, in _get_response
    response = wrapped_callback(request, *callback_args, **callback_kwargs)
  File "C:\Users\Sahil Arora\Desktop\SCP-B\venv\lib\site-packages\django\views\decorators\csrf.py", line 54, in wrapped_view
    return view_func(*args, **kwargs)
  File "C:\Users\Sahil Arora\Desktop\SCP-B\venv\lib\site-packages\django\views\generic\base.py", line 71, in view
    return self.dispatch(request, *args, **kwargs)
  File "C:\Users\Sahil Arora\Desktop\SCP-B\venv\lib\site-packages\rest_framework\views.py", line 505, in dispatch
    response = self.handle_exception(exc)
  File "C:\Users\Sahil Arora\Desktop\SCP-B\venv\lib\site-packages\rest_framework\views.py", line 465, in handle_exception
    self.raise_uncaught_exception(exc)
  File "C:\Users\Sahil Arora\Desktop\SCP-B\venv\lib\site-packages\rest_framework\views.py", line 476, in raise_uncaught_exception
    raise exc
  File "C:\Users\Sahil Arora\Desktop\SCP-B\venv\lib\site-packages\rest_framework\views.py", line 502, in dispatch
    response = handler(request, *args, **kwargs)
TypeError: get() got an unexpected keyword argument 'otp'
2020-09-24 00:13:29,989 INFO     [autoreload.py:222] C:\Users\Sahil Arora\Desktop\SCP-B\SCP-backened\SCPapp\models.py changed, reloading.
2020-09-24 00:13:40,855 ERROR    [log.py:228] Internal Server Error: /confirmEmailID/6514/
Traceback (most recent call last):
  File "C:\Users\Sahil Arora\Desktop\SCP-B\venv\lib\site-packages\django\core\handlers\exception.py", line 34, in inner
    response = get_response(request)
  File "C:\Users\Sahil Arora\Desktop\SCP-B\venv\lib\site-packages\django\core\handlers\base.py", line 115, in _get_response
    response = self.process_exception_by_middleware(e, request)
  File "C:\Users\Sahil Arora\Desktop\SCP-B\venv\lib\site-packages\django\core\handlers\base.py", line 113, in _get_response
    response = wrapped_callback(request, *callback_args, **callback_kwargs)
  File "C:\Users\Sahil Arora\Desktop\SCP-B\venv\lib\site-packages\django\views\decorators\csrf.py", line 54, in wrapped_view
    return view_func(*args, **kwargs)
  File "C:\Users\Sahil Arora\Desktop\SCP-B\venv\lib\site-packages\django\views\generic\base.py", line 71, in view
    return self.dispatch(request, *args, **kwargs)
  File "C:\Users\Sahil Arora\Desktop\SCP-B\venv\lib\site-packages\rest_framework\views.py", line 505, in dispatch
    response = self.handle_exception(exc)
  File "C:\Users\Sahil Arora\Desktop\SCP-B\venv\lib\site-packages\rest_framework\views.py", line 465, in handle_exception
    self.raise_uncaught_exception(exc)
  File "C:\Users\Sahil Arora\Desktop\SCP-B\venv\lib\site-packages\rest_framework\views.py", line 476, in raise_uncaught_exception
    raise exc
  File "C:\Users\Sahil Arora\Desktop\SCP-B\venv\lib\site-packages\rest_framework\views.py", line 502, in dispatch
    response = handler(request, *args, **kwargs)
TypeError: get() got an unexpected keyword argument 'otp'
2020-09-24 00:14:37,721 INFO     [autoreload.py:222] C:\Users\Sahil Arora\Desktop\SCP-B\SCP-backened\SCPapp\views.py changed, reloading.
2020-09-24 00:14:50,578 ERROR    [log.py:228] Internal Server Error: /confirmEmailID/6514/
Traceback (most recent call last):
  File "C:\Users\Sahil Arora\Desktop\SCP-B\venv\lib\site-packages\django\core\handlers\exception.py", line 34, in inner
    response = get_response(request)
  File "C:\Users\Sahil Arora\Desktop\SCP-B\venv\lib\site-packages\django\core\handlers\base.py", line 115, in _get_response
    response = self.process_exception_by_middleware(e, request)
  File "C:\Users\Sahil Arora\Desktop\SCP-B\venv\lib\site-packages\django\core\handlers\base.py", line 113, in _get_response
    response = wrapped_callback(request, *callback_args, **callback_kwargs)
  File "C:\Users\Sahil Arora\Desktop\SCP-B\venv\lib\site-packages\django\views\decorators\csrf.py", line 54, in wrapped_view
    return view_func(*args, **kwargs)
  File "C:\Users\Sahil Arora\Desktop\SCP-B\venv\lib\site-packages\django\views\generic\base.py", line 71, in view
    return self.dispatch(request, *args, **kwargs)
  File "C:\Users\Sahil Arora\Desktop\SCP-B\venv\lib\site-packages\rest_framework\views.py", line 505, in dispatch
    response = self.handle_exception(exc)
  File "C:\Users\Sahil Arora\Desktop\SCP-B\venv\lib\site-packages\rest_framework\views.py", line 465, in handle_exception
    self.raise_uncaught_exception(exc)
  File "C:\Users\Sahil Arora\Desktop\SCP-B\venv\lib\site-packages\rest_framework\views.py", line 476, in raise_uncaught_exception
    raise exc
  File "C:\Users\Sahil Arora\Desktop\SCP-B\venv\lib\site-packages\rest_framework\views.py", line 502, in dispatch
    response = handler(request, *args, **kwargs)
TypeError: get() got an unexpected keyword argument 'otp'
2020-09-24 00:15:33,878 INFO     [autoreload.py:222] C:\Users\Sahil Arora\Desktop\SCP-B\SCP-backened\SCP\urls.py changed, reloading.
2020-09-24 00:15:43,123 ERROR    [log.py:228] Internal Server Error: /confirmEmailID/6514/
Traceback (most recent call last):
  File "C:\Users\Sahil Arora\Desktop\SCP-B\venv\lib\site-packages\django\core\handlers\exception.py", line 34, in inner
    response = get_response(request)
  File "C:\Users\Sahil Arora\Desktop\SCP-B\venv\lib\site-packages\django\core\handlers\base.py", line 115, in _get_response
    response = self.process_exception_by_middleware(e, request)
  File "C:\Users\Sahil Arora\Desktop\SCP-B\venv\lib\site-packages\django\core\handlers\base.py", line 113, in _get_response
    response = wrapped_callback(request, *callback_args, **callback_kwargs)
  File "C:\Users\Sahil Arora\Desktop\SCP-B\venv\lib\site-packages\django\views\decorators\csrf.py", line 54, in wrapped_view
    return view_func(*args, **kwargs)
  File "C:\Users\Sahil Arora\Desktop\SCP-B\venv\lib\site-packages\django\views\generic\base.py", line 71, in view
    return self.dispatch(request, *args, **kwargs)
  File "C:\Users\Sahil Arora\Desktop\SCP-B\venv\lib\site-packages\rest_framework\views.py", line 505, in dispatch
    response = self.handle_exception(exc)
  File "C:\Users\Sahil Arora\Desktop\SCP-B\venv\lib\site-packages\rest_framework\views.py", line 465, in handle_exception
    self.raise_uncaught_exception(exc)
  File "C:\Users\Sahil Arora\Desktop\SCP-B\venv\lib\site-packages\rest_framework\views.py", line 476, in raise_uncaught_exception
    raise exc
  File "C:\Users\Sahil Arora\Desktop\SCP-B\venv\lib\site-packages\rest_framework\views.py", line 502, in dispatch
    response = handler(request, *args, **kwargs)
TypeError: get() got an unexpected keyword argument 'otp'
2020-09-24 00:16:41,539 INFO     [autoreload.py:222] C:\Users\Sahil Arora\Desktop\SCP-B\SCP-backened\SCP\urls.py changed, reloading.
2020-09-24 00:17:35,410 ERROR    [log.py:228] Internal Server Error: /confirmEmailID/6514/
Traceback (most recent call last):
  File "C:\Users\Sahil Arora\Desktop\SCP-B\venv\lib\site-packages\django\core\handlers\exception.py", line 34, in inner
    response = get_response(request)
  File "C:\Users\Sahil Arora\Desktop\SCP-B\venv\lib\site-packages\django\core\handlers\base.py", line 115, in _get_response
    response = self.process_exception_by_middleware(e, request)
  File "C:\Users\Sahil Arora\Desktop\SCP-B\venv\lib\site-packages\django\core\handlers\base.py", line 113, in _get_response
    response = wrapped_callback(request, *callback_args, **callback_kwargs)
  File "C:\Users\Sahil Arora\Desktop\SCP-B\venv\lib\site-packages\django\views\decorators\csrf.py", line 54, in wrapped_view
    return view_func(*args, **kwargs)
  File "C:\Users\Sahil Arora\Desktop\SCP-B\venv\lib\site-packages\django\views\generic\base.py", line 71, in view
    return self.dispatch(request, *args, **kwargs)
  File "C:\Users\Sahil Arora\Desktop\SCP-B\venv\lib\site-packages\rest_framework\views.py", line 505, in dispatch
    response = self.handle_exception(exc)
  File "C:\Users\Sahil Arora\Desktop\SCP-B\venv\lib\site-packages\rest_framework\views.py", line 465, in handle_exception
    self.raise_uncaught_exception(exc)
  File "C:\Users\Sahil Arora\Desktop\SCP-B\venv\lib\site-packages\rest_framework\views.py", line 476, in raise_uncaught_exception
    raise exc
  File "C:\Users\Sahil Arora\Desktop\SCP-B\venv\lib\site-packages\rest_framework\views.py", line 502, in dispatch
    response = handler(request, *args, **kwargs)
TypeError: get() got an unexpected keyword argument 'id'
2020-09-24 00:17:47,758 INFO     [autoreload.py:222] C:\Users\Sahil Arora\Desktop\SCP-B\SCP-backened\SCP\urls.py changed, reloading.
2020-09-24 00:17:56,982 ERROR    [log.py:228] Internal Server Error: /confirmEmailID/6514/
Traceback (most recent call last):
  File "C:\Users\Sahil Arora\Desktop\SCP-B\venv\lib\site-packages\django\core\handlers\exception.py", line 34, in inner
    response = get_response(request)
  File "C:\Users\Sahil Arora\Desktop\SCP-B\venv\lib\site-packages\django\core\handlers\base.py", line 115, in _get_response
    response = self.process_exception_by_middleware(e, request)
  File "C:\Users\Sahil Arora\Desktop\SCP-B\venv\lib\site-packages\django\core\handlers\base.py", line 113, in _get_response
    response = wrapped_callback(request, *callback_args, **callback_kwargs)
  File "C:\Users\Sahil Arora\Desktop\SCP-B\venv\lib\site-packages\django\views\decorators\csrf.py", line 54, in wrapped_view
    return view_func(*args, **kwargs)
  File "C:\Users\Sahil Arora\Desktop\SCP-B\venv\lib\site-packages\django\views\generic\base.py", line 71, in view
    return self.dispatch(request, *args, **kwargs)
  File "C:\Users\Sahil Arora\Desktop\SCP-B\venv\lib\site-packages\rest_framework\views.py", line 505, in dispatch
    response = self.handle_exception(exc)
  File "C:\Users\Sahil Arora\Desktop\SCP-B\venv\lib\site-packages\rest_framework\views.py", line 465, in handle_exception
    self.raise_uncaught_exception(exc)
  File "C:\Users\Sahil Arora\Desktop\SCP-B\venv\lib\site-packages\rest_framework\views.py", line 476, in raise_uncaught_exception
    raise exc
  File "C:\Users\Sahil Arora\Desktop\SCP-B\venv\lib\site-packages\rest_framework\views.py", line 502, in dispatch
    response = handler(request, *args, **kwargs)
TypeError: get() got an unexpected keyword argument 'otp'
2020-09-24 00:18:42,197 INFO     [autoreload.py:222] C:\Users\Sahil Arora\Desktop\SCP-B\SCP-backened\SCPapp\views.py changed, reloading.
2020-09-24 00:19:18,142 INFO     [autoreload.py:222] C:\Users\Sahil Arora\Desktop\SCP-B\SCP-backened\SCPapp\views.py changed, reloading.
2020-09-24 00:19:57,893 WARNING  [log.py:228] Not Found: /
2020-09-24 00:21:22,520 INFO     [autoreload.py:222] C:\Users\Sahil Arora\Desktop\SCP-B\SCP-backened\SCPapp\views.py changed, reloading.
2020-09-24 00:22:04,792 ERROR    [log.py:228] Internal Server Error: /confirmEmailID/
Traceback (most recent call last):
  File "C:\Users\Sahil Arora\Desktop\SCP-B\venv\lib\site-packages\django\core\handlers\exception.py", line 34, in inner
    response = get_response(request)
  File "C:\Users\Sahil Arora\Desktop\SCP-B\venv\lib\site-packages\django\core\handlers\base.py", line 115, in _get_response
    response = self.process_exception_by_middleware(e, request)
  File "C:\Users\Sahil Arora\Desktop\SCP-B\venv\lib\site-packages\django\core\handlers\base.py", line 113, in _get_response
    response = wrapped_callback(request, *callback_args, **callback_kwargs)
  File "C:\Users\Sahil Arora\Desktop\SCP-B\venv\lib\site-packages\django\views\decorators\csrf.py", line 54, in wrapped_view
    return view_func(*args, **kwargs)
  File "C:\Users\Sahil Arora\Desktop\SCP-B\venv\lib\site-packages\django\views\generic\base.py", line 71, in view
    return self.dispatch(request, *args, **kwargs)
  File "C:\Users\Sahil Arora\Desktop\SCP-B\venv\lib\site-packages\rest_framework\views.py", line 505, in dispatch
    response = self.handle_exception(exc)
  File "C:\Users\Sahil Arora\Desktop\SCP-B\venv\lib\site-packages\rest_framework\views.py", line 465, in handle_exception
    self.raise_uncaught_exception(exc)
  File "C:\Users\Sahil Arora\Desktop\SCP-B\venv\lib\site-packages\rest_framework\views.py", line 476, in raise_uncaught_exception
    raise exc
  File "C:\Users\Sahil Arora\Desktop\SCP-B\venv\lib\site-packages\rest_framework\views.py", line 502, in dispatch
    response = handler(request, *args, **kwargs)
TypeError: get() missing 1 required positional argument: 'otp'
2020-09-24 00:29:17,497 ERROR    [log.py:228] Internal Server Error: /confirmEmailID/
Traceback (most recent call last):
  File "C:\Users\Sahil Arora\Desktop\SCP-B\venv\lib\site-packages\django\core\handlers\exception.py", line 34, in inner
    response = get_response(request)
  File "C:\Users\Sahil Arora\Desktop\SCP-B\venv\lib\site-packages\django\core\handlers\base.py", line 145, in _get_response
    response = self.process_exception_by_middleware(e, request)
  File "C:\Users\Sahil Arora\Desktop\SCP-B\venv\lib\site-packages\django\core\handlers\base.py", line 143, in _get_response
    response = response.render()
  File "C:\Users\Sahil Arora\Desktop\SCP-B\venv\lib\site-packages\django\template\response.py", line 105, in render
    self.content = self.rendered_content
  File "C:\Users\Sahil Arora\Desktop\SCP-B\venv\lib\site-packages\rest_framework\response.py", line 70, in rendered_content
    ret = renderer.render(self.data, accepted_media_type, context)
  File "C:\Users\Sahil Arora\Desktop\SCP-B\venv\lib\site-packages\rest_framework\renderers.py", line 103, in render
    allow_nan=not self.strict, separators=separators
  File "C:\Users\Sahil Arora\Desktop\SCP-B\venv\lib\site-packages\rest_framework\utils\json.py", line 25, in dumps
    return json.dumps(*args, **kwargs)
  File "C:\Users\Sahil Arora\AppData\Local\Programs\Python\Python36\lib\json\__init__.py", line 238, in dumps
    **kw).encode(obj)
  File "C:\Users\Sahil Arora\AppData\Local\Programs\Python\Python36\lib\json\encoder.py", line 199, in encode
    chunks = self.iterencode(o, _one_shot=True)
  File "C:\Users\Sahil Arora\AppData\Local\Programs\Python\Python36\lib\json\encoder.py", line 257, in iterencode
    return _iterencode(o, 0)
  File "C:\Users\Sahil Arora\Desktop\SCP-B\venv\lib\site-packages\rest_framework\utils\encoders.py", line 67, in default
    return super().default(obj)
  File "C:\Users\Sahil Arora\AppData\Local\Programs\Python\Python36\lib\json\encoder.py", line 180, in default
    o.__class__.__name__)
TypeError: Object of type 'property' is not JSON serializable
2020-09-24 07:24:47,367 INFO     [autoreload.py:222] C:\Users\Sahil Arora\Desktop\SCP-B\SCP-backened\SCPapp\views.py changed, reloading.
2020-09-24 07:28:28,296 WARNING  [log.py:228] Not Found: /verifyEmailID/
2020-09-24 07:28:46,958 INFO     [autoreload.py:222] C:\Users\Sahil Arora\Desktop\SCP-B\SCP-backened\SCP\urls.py changed, reloading.
2020-09-24 07:29:58,986 INFO     [autoreload.py:222] C:\Users\Sahil Arora\Desktop\SCP-B\SCP-backened\SCPapp\views.py changed, reloading.
2020-09-24 07:34:05,322 INFO     [autoreload.py:222] C:\Users\Sahil Arora\Desktop\SCP-B\SCP-backened\SCPapp\views.py changed, reloading.
2020-09-24 07:34:42,843 ERROR    [log.py:228] Internal Server Error: /verifyEmailID/
Traceback (most recent call last):
  File "C:\Users\Sahil Arora\Desktop\SCP-B\venv\lib\site-packages\django\core\handlers\exception.py", line 34, in inner
    response = get_response(request)
  File "C:\Users\Sahil Arora\Desktop\SCP-B\venv\lib\site-packages\django\core\handlers\base.py", line 115, in _get_response
    response = self.process_exception_by_middleware(e, request)
  File "C:\Users\Sahil Arora\Desktop\SCP-B\venv\lib\site-packages\django\core\handlers\base.py", line 113, in _get_response
    response = wrapped_callback(request, *callback_args, **callback_kwargs)
  File "C:\Users\Sahil Arora\Desktop\SCP-B\venv\lib\site-packages\django\views\decorators\csrf.py", line 54, in wrapped_view
    return view_func(*args, **kwargs)
  File "C:\Users\Sahil Arora\Desktop\SCP-B\venv\lib\site-packages\django\views\generic\base.py", line 71, in view
    return self.dispatch(request, *args, **kwargs)
  File "C:\Users\Sahil Arora\Desktop\SCP-B\venv\lib\site-packages\rest_framework\views.py", line 505, in dispatch
    response = self.handle_exception(exc)
  File "C:\Users\Sahil Arora\Desktop\SCP-B\venv\lib\site-packages\rest_framework\views.py", line 465, in handle_exception
    self.raise_uncaught_exception(exc)
  File "C:\Users\Sahil Arora\Desktop\SCP-B\venv\lib\site-packages\rest_framework\views.py", line 476, in raise_uncaught_exception
    raise exc
  File "C:\Users\Sahil Arora\Desktop\SCP-B\venv\lib\site-packages\rest_framework\views.py", line 502, in dispatch
    response = handler(request, *args, **kwargs)
  File "C:\Users\Sahil Arora\Desktop\SCP-B\SCP-backened\SCPapp\views.py", line 66, in post
    if serializer.is_valid():
  File "C:\Users\Sahil Arora\Desktop\SCP-B\venv\lib\site-packages\rest_framework\serializers.py", line 228, in is_valid
    'Cannot call `.is_valid()` as no `data=` keyword argument was '
AssertionError: Cannot call `.is_valid()` as no `data=` keyword argument was passed when instantiating the serializer instance.
2020-09-24 07:47:04,415 INFO     [autoreload.py:222] C:\Users\Sahil Arora\Desktop\SCP-B\SCP-backened\SCPapp\views.py changed, reloading.
2020-09-24 07:47:42,480 ERROR    [log.py:228] Internal Server Error: /verifyEmailID/
Traceback (most recent call last):
  File "C:\Users\Sahil Arora\Desktop\SCP-B\venv\lib\site-packages\django\core\handlers\exception.py", line 34, in inner
    response = get_response(request)
  File "C:\Users\Sahil Arora\Desktop\SCP-B\venv\lib\site-packages\django\core\handlers\base.py", line 145, in _get_response
    response = self.process_exception_by_middleware(e, request)
  File "C:\Users\Sahil Arora\Desktop\SCP-B\venv\lib\site-packages\django\core\handlers\base.py", line 143, in _get_response
    response = response.render()
  File "C:\Users\Sahil Arora\Desktop\SCP-B\venv\lib\site-packages\django\template\response.py", line 105, in render
    self.content = self.rendered_content
  File "C:\Users\Sahil Arora\Desktop\SCP-B\venv\lib\site-packages\rest_framework\response.py", line 70, in rendered_content
    ret = renderer.render(self.data, accepted_media_type, context)
  File "C:\Users\Sahil Arora\Desktop\SCP-B\venv\lib\site-packages\rest_framework\renderers.py", line 103, in render
    allow_nan=not self.strict, separators=separators
  File "C:\Users\Sahil Arora\Desktop\SCP-B\venv\lib\site-packages\rest_framework\utils\json.py", line 25, in dumps
    return json.dumps(*args, **kwargs)
  File "C:\Users\Sahil Arora\AppData\Local\Programs\Python\Python36\lib\json\__init__.py", line 238, in dumps
    **kw).encode(obj)
  File "C:\Users\Sahil Arora\AppData\Local\Programs\Python\Python36\lib\json\encoder.py", line 199, in encode
    chunks = self.iterencode(o, _one_shot=True)
  File "C:\Users\Sahil Arora\AppData\Local\Programs\Python\Python36\lib\json\encoder.py", line 257, in iterencode
    return _iterencode(o, 0)
  File "C:\Users\Sahil Arora\Desktop\SCP-B\venv\lib\site-packages\rest_framework\utils\encoders.py", line 67, in default
    return super().default(obj)
  File "C:\Users\Sahil Arora\AppData\Local\Programs\Python\Python36\lib\json\encoder.py", line 180, in default
    o.__class__.__name__)
TypeError: Object of type 'property' is not JSON serializable
2020-09-24 07:49:50,676 INFO     [autoreload.py:222] C:\Users\Sahil Arora\Desktop\SCP-B\SCP-backened\SCPapp\views.py changed, reloading.
2020-09-24 07:50:07,658 ERROR    [log.py:228] Internal Server Error: /verifyEmailID/
Traceback (most recent call last):
  File "C:\Users\Sahil Arora\Desktop\SCP-B\venv\lib\site-packages\django\core\handlers\exception.py", line 34, in inner
    response = get_response(request)
  File "C:\Users\Sahil Arora\Desktop\SCP-B\venv\lib\site-packages\django\core\handlers\base.py", line 115, in _get_response
    response = self.process_exception_by_middleware(e, request)
  File "C:\Users\Sahil Arora\Desktop\SCP-B\venv\lib\site-packages\django\core\handlers\base.py", line 113, in _get_response
    response = wrapped_callback(request, *callback_args, **callback_kwargs)
  File "C:\Users\Sahil Arora\Desktop\SCP-B\venv\lib\site-packages\django\views\decorators\csrf.py", line 54, in wrapped_view
    return view_func(*args, **kwargs)
  File "C:\Users\Sahil Arora\Desktop\SCP-B\venv\lib\site-packages\django\views\generic\base.py", line 71, in view
    return self.dispatch(request, *args, **kwargs)
  File "C:\Users\Sahil Arora\Desktop\SCP-B\venv\lib\site-packages\rest_framework\views.py", line 505, in dispatch
    response = self.handle_exception(exc)
  File "C:\Users\Sahil Arora\Desktop\SCP-B\venv\lib\site-packages\rest_framework\views.py", line 465, in handle_exception
    self.raise_uncaught_exception(exc)
  File "C:\Users\Sahil Arora\Desktop\SCP-B\venv\lib\site-packages\rest_framework\views.py", line 476, in raise_uncaught_exception
    raise exc
  File "C:\Users\Sahil Arora\Desktop\SCP-B\venv\lib\site-packages\rest_framework\views.py", line 502, in dispatch
    response = handler(request, *args, **kwargs)
  File "C:\Users\Sahil Arora\Desktop\SCP-B\SCP-backened\SCPapp\views.py", line 67, in post
    return Response(serializer.data)
  File "C:\Users\Sahil Arora\Desktop\SCP-B\venv\lib\site-packages\rest_framework\serializers.py", line 562, in data
    ret = super().data
  File "C:\Users\Sahil Arora\Desktop\SCP-B\venv\lib\site-packages\rest_framework\serializers.py", line 256, in data
    raise AssertionError(msg)
AssertionError: When a serializer is passed a `data` keyword argument you must call `.is_valid()` before attempting to access the serialized `.data` representation.
You should either call `.is_valid()` first, or access `.initial_data` instead.
2020-09-24 07:51:47,638 INFO     [autoreload.py:222] C:\Users\Sahil Arora\Desktop\SCP-B\SCP-backened\SCPapp\views.py changed, reloading.
2020-09-24 07:52:42,327 INFO     [autoreload.py:222] C:\Users\Sahil Arora\Desktop\SCP-B\SCP-backened\SCPapp\views.py changed, reloading.
2020-09-24 07:54:15,454 INFO     [autoreload.py:222] C:\Users\Sahil Arora\Desktop\SCP-B\SCP-backened\SCPapp\views.py changed, reloading.
2020-09-24 07:55:04,489 INFO     [autoreload.py:222] C:\Users\Sahil Arora\Desktop\SCP-B\SCP-backened\SCPapp\views.py changed, reloading.
2020-09-24 07:55:21,180 WARNING  [log.py:228] Not Found: /verifyEmailID/
2020-09-24 07:55:46,567 WARNING  [log.py:228] Not Found: /confirmEmailID/6918/
2020-09-24 07:56:10,490 INFO     [autoreload.py:222] C:\Users\Sahil Arora\Desktop\SCP-B\SCP-backened\SCPapp\views.py changed, reloading.
2020-09-24 07:57:10,837 ERROR    [log.py:228] Internal Server Error: /confirmEmailID/
Traceback (most recent call last):
  File "C:\Users\Sahil Arora\Desktop\SCP-B\venv\lib\site-packages\django\core\handlers\exception.py", line 34, in inner
    response = get_response(request)
  File "C:\Users\Sahil Arora\Desktop\SCP-B\venv\lib\site-packages\django\core\handlers\base.py", line 145, in _get_response
    response = self.process_exception_by_middleware(e, request)
  File "C:\Users\Sahil Arora\Desktop\SCP-B\venv\lib\site-packages\django\core\handlers\base.py", line 143, in _get_response
    response = response.render()
  File "C:\Users\Sahil Arora\Desktop\SCP-B\venv\lib\site-packages\django\template\response.py", line 105, in render
    self.content = self.rendered_content
  File "C:\Users\Sahil Arora\Desktop\SCP-B\venv\lib\site-packages\rest_framework\response.py", line 70, in rendered_content
    ret = renderer.render(self.data, accepted_media_type, context)
  File "C:\Users\Sahil Arora\Desktop\SCP-B\venv\lib\site-packages\rest_framework\renderers.py", line 103, in render
    allow_nan=not self.strict, separators=separators
  File "C:\Users\Sahil Arora\Desktop\SCP-B\venv\lib\site-packages\rest_framework\utils\json.py", line 25, in dumps
    return json.dumps(*args, **kwargs)
  File "C:\Users\Sahil Arora\AppData\Local\Programs\Python\Python36\lib\json\__init__.py", line 238, in dumps
    **kw).encode(obj)
  File "C:\Users\Sahil Arora\AppData\Local\Programs\Python\Python36\lib\json\encoder.py", line 199, in encode
    chunks = self.iterencode(o, _one_shot=True)
  File "C:\Users\Sahil Arora\AppData\Local\Programs\Python\Python36\lib\json\encoder.py", line 257, in iterencode
    return _iterencode(o, 0)
  File "C:\Users\Sahil Arora\Desktop\SCP-B\venv\lib\site-packages\rest_framework\utils\encoders.py", line 67, in default
    return super().default(obj)
  File "C:\Users\Sahil Arora\AppData\Local\Programs\Python\Python36\lib\json\encoder.py", line 180, in default
    o.__class__.__name__)
TypeError: Object of type 'property' is not JSON serializable
2020-09-24 07:59:05,625 WARNING  [log.py:228] Not Found: /verifyEmailID/
2020-09-24 08:29:22,970 ERROR    [log.py:228] Internal Server Error: /confirmEmailID/
Traceback (most recent call last):
  File "C:\Users\Sahil Arora\Desktop\SCP-B\venv\lib\site-packages\django\core\handlers\exception.py", line 34, in inner
    response = get_response(request)
  File "C:\Users\Sahil Arora\Desktop\SCP-B\venv\lib\site-packages\django\core\handlers\base.py", line 115, in _get_response
    response = self.process_exception_by_middleware(e, request)
  File "C:\Users\Sahil Arora\Desktop\SCP-B\venv\lib\site-packages\django\core\handlers\base.py", line 113, in _get_response
    response = wrapped_callback(request, *callback_args, **callback_kwargs)
  File "C:\Users\Sahil Arora\Desktop\SCP-B\venv\lib\site-packages\django\views\decorators\csrf.py", line 54, in wrapped_view
    return view_func(*args, **kwargs)
  File "C:\Users\Sahil Arora\Desktop\SCP-B\venv\lib\site-packages\django\views\generic\base.py", line 71, in view
    return self.dispatch(request, *args, **kwargs)
  File "C:\Users\Sahil Arora\Desktop\SCP-B\venv\lib\site-packages\rest_framework\views.py", line 505, in dispatch
    response = self.handle_exception(exc)
  File "C:\Users\Sahil Arora\Desktop\SCP-B\venv\lib\site-packages\rest_framework\views.py", line 465, in handle_exception
    self.raise_uncaught_exception(exc)
  File "C:\Users\Sahil Arora\Desktop\SCP-B\venv\lib\site-packages\rest_framework\views.py", line 476, in raise_uncaught_exception
    raise exc
  File "C:\Users\Sahil Arora\Desktop\SCP-B\venv\lib\site-packages\rest_framework\views.py", line 502, in dispatch
    response = handler(request, *args, **kwargs)
  File "C:\Users\Sahil Arora\Desktop\SCP-B\SCP-backened\SCPapp\views.py", line 38, in post
    [request.data["EmailId"]], fail_silently=False, )
KeyError: 'EmailId'
2020-09-24 08:30:48,944 INFO     [autoreload.py:222] C:\Users\Sahil Arora\Desktop\SCP-B\SCP-backened\SCPapp\models.py changed, reloading.
2020-09-24 08:31:52,448 ERROR    [log.py:228] Internal Server Error: /confirmEmailID/
Traceback (most recent call last):
  File "C:\Users\Sahil Arora\Desktop\SCP-B\venv\lib\site-packages\django\db\backends\utils.py", line 86, in _execute
    return self.cursor.execute(sql, params)
  File "C:\Users\Sahil Arora\Desktop\SCP-B\venv\lib\site-packages\django\db\backends\sqlite3\base.py", line 396, in execute
    return Database.Cursor.execute(self, query, params)
sqlite3.OperationalError: table SCPapp_emailverify has no column named email

The above exception was the direct cause of the following exception:

Traceback (most recent call last):
  File "C:\Users\Sahil Arora\Desktop\SCP-B\venv\lib\site-packages\django\core\handlers\exception.py", line 34, in inner
    response = get_response(request)
  File "C:\Users\Sahil Arora\Desktop\SCP-B\venv\lib\site-packages\django\core\handlers\base.py", line 115, in _get_response
    response = self.process_exception_by_middleware(e, request)
  File "C:\Users\Sahil Arora\Desktop\SCP-B\venv\lib\site-packages\django\core\handlers\base.py", line 113, in _get_response
    response = wrapped_callback(request, *callback_args, **callback_kwargs)
  File "C:\Users\Sahil Arora\Desktop\SCP-B\venv\lib\site-packages\django\views\decorators\csrf.py", line 54, in wrapped_view
    return view_func(*args, **kwargs)
  File "C:\Users\Sahil Arora\Desktop\SCP-B\venv\lib\site-packages\django\views\generic\base.py", line 71, in view
    return self.dispatch(request, *args, **kwargs)
  File "C:\Users\Sahil Arora\Desktop\SCP-B\venv\lib\site-packages\rest_framework\views.py", line 505, in dispatch
    response = self.handle_exception(exc)
  File "C:\Users\Sahil Arora\Desktop\SCP-B\venv\lib\site-packages\rest_framework\views.py", line 465, in handle_exception
    self.raise_uncaught_exception(exc)
  File "C:\Users\Sahil Arora\Desktop\SCP-B\venv\lib\site-packages\rest_framework\views.py", line 476, in raise_uncaught_exception
    raise exc
  File "C:\Users\Sahil Arora\Desktop\SCP-B\venv\lib\site-packages\rest_framework\views.py", line 502, in dispatch
    response = handler(request, *args, **kwargs)
  File "C:\Users\Sahil Arora\Desktop\SCP-B\SCP-backened\SCPapp\views.py", line 40, in post
    emailVerify.save()
  File "C:\Users\Sahil Arora\Desktop\SCP-B\venv\lib\site-packages\rest_framework\serializers.py", line 212, in save
    self.instance = self.create(validated_data)
  File "C:\Users\Sahil Arora\Desktop\SCP-B\venv\lib\site-packages\rest_framework\serializers.py", line 948, in create
    instance = ModelClass._default_manager.create(**validated_data)
  File "C:\Users\Sahil Arora\Desktop\SCP-B\venv\lib\site-packages\django\db\models\manager.py", line 82, in manager_method
    return getattr(self.get_queryset(), name)(*args, **kwargs)
  File "C:\Users\Sahil Arora\Desktop\SCP-B\venv\lib\site-packages\django\db\models\query.py", line 433, in create
    obj.save(force_insert=True, using=self.db)
  File "C:\Users\Sahil Arora\Desktop\SCP-B\venv\lib\site-packages\django\db\models\base.py", line 746, in save
    force_update=force_update, update_fields=update_fields)
  File "C:\Users\Sahil Arora\Desktop\SCP-B\venv\lib\site-packages\django\db\models\base.py", line 784, in save_base
    force_update, using, update_fields,
  File "C:\Users\Sahil Arora\Desktop\SCP-B\venv\lib\site-packages\django\db\models\base.py", line 887, in _save_table
    results = self._do_insert(cls._base_manager, using, fields, returning_fields, raw)
  File "C:\Users\Sahil Arora\Desktop\SCP-B\venv\lib\site-packages\django\db\models\base.py", line 926, in _do_insert
    using=using, raw=raw,
  File "C:\Users\Sahil Arora\Desktop\SCP-B\venv\lib\site-packages\django\db\models\manager.py", line 82, in manager_method
    return getattr(self.get_queryset(), name)(*args, **kwargs)
  File "C:\Users\Sahil Arora\Desktop\SCP-B\venv\lib\site-packages\django\db\models\query.py", line 1204, in _insert
    return query.get_compiler(using=using).execute_sql(returning_fields)
  File "C:\Users\Sahil Arora\Desktop\SCP-B\venv\lib\site-packages\django\db\models\sql\compiler.py", line 1391, in execute_sql
    cursor.execute(sql, params)
  File "C:\Users\Sahil Arora\Desktop\SCP-B\venv\lib\site-packages\django\db\backends\utils.py", line 100, in execute
    return super().execute(sql, params)
  File "C:\Users\Sahil Arora\Desktop\SCP-B\venv\lib\site-packages\django\db\backends\utils.py", line 68, in execute
    return self._execute_with_wrappers(sql, params, many=False, executor=self._execute)
  File "C:\Users\Sahil Arora\Desktop\SCP-B\venv\lib\site-packages\django\db\backends\utils.py", line 77, in _execute_with_wrappers
    return executor(sql, params, many, context)
  File "C:\Users\Sahil Arora\Desktop\SCP-B\venv\lib\site-packages\django\db\backends\utils.py", line 86, in _execute
    return self.cursor.execute(sql, params)
  File "C:\Users\Sahil Arora\Desktop\SCP-B\venv\lib\site-packages\django\db\utils.py", line 90, in __exit__
    raise dj_exc_value.with_traceback(traceback) from exc_value
  File "C:\Users\Sahil Arora\Desktop\SCP-B\venv\lib\site-packages\django\db\backends\utils.py", line 86, in _execute
    return self.cursor.execute(sql, params)
  File "C:\Users\Sahil Arora\Desktop\SCP-B\venv\lib\site-packages\django\db\backends\sqlite3\base.py", line 396, in execute
    return Database.Cursor.execute(self, query, params)
django.db.utils.OperationalError: table SCPapp_emailverify has no column named email
2020-09-24 08:43:29,617 ERROR    [log.py:228] Internal Server Error: /verifyEmailID/
Traceback (most recent call last):
  File "C:\Users\Sahil Arora\Desktop\SCP-B\venv\lib\site-packages\django\core\handlers\exception.py", line 34, in inner
    response = get_response(request)
  File "C:\Users\Sahil Arora\Desktop\SCP-B\venv\lib\site-packages\django\core\handlers\base.py", line 115, in _get_response
    response = self.process_exception_by_middleware(e, request)
  File "C:\Users\Sahil Arora\Desktop\SCP-B\venv\lib\site-packages\django\core\handlers\base.py", line 113, in _get_response
    response = wrapped_callback(request, *callback_args, **callback_kwargs)
  File "C:\Users\Sahil Arora\Desktop\SCP-B\venv\lib\site-packages\django\views\decorators\csrf.py", line 54, in wrapped_view
    return view_func(*args, **kwargs)
  File "C:\Users\Sahil Arora\Desktop\SCP-B\venv\lib\site-packages\django\views\generic\base.py", line 71, in view
    return self.dispatch(request, *args, **kwargs)
  File "C:\Users\Sahil Arora\Desktop\SCP-B\venv\lib\site-packages\rest_framework\views.py", line 505, in dispatch
    response = self.handle_exception(exc)
  File "C:\Users\Sahil Arora\Desktop\SCP-B\venv\lib\site-packages\rest_framework\views.py", line 465, in handle_exception
    self.raise_uncaught_exception(exc)
  File "C:\Users\Sahil Arora\Desktop\SCP-B\venv\lib\site-packages\rest_framework\views.py", line 476, in raise_uncaught_exception
    raise exc
  File "C:\Users\Sahil Arora\Desktop\SCP-B\venv\lib\site-packages\rest_framework\views.py", line 502, in dispatch
    response = handler(request, *args, **kwargs)
  File "C:\Users\Sahil Arora\Desktop\SCP-B\SCP-backened\SCPapp\views.py", line 65, in post
    emailVerify = self.get_object(request.data["otp"])
KeyError: 'otp'
2020-09-24 08:44:29,211 WARNING  [log.py:228] Not Found: /verifyEmailID/
2020-09-24 08:44:51,159 ERROR    [log.py:228] Internal Server Error: /admin/SCPapp/emailverify/MT201913/change/
Traceback (most recent call last):
  File "C:\Users\Sahil Arora\Desktop\SCP-B\venv\lib\site-packages\django\core\handlers\exception.py", line 34, in inner
    response = get_response(request)
  File "C:\Users\Sahil Arora\Desktop\SCP-B\venv\lib\site-packages\django\core\handlers\base.py", line 145, in _get_response
    response = self.process_exception_by_middleware(e, request)
  File "C:\Users\Sahil Arora\Desktop\SCP-B\venv\lib\site-packages\django\core\handlers\base.py", line 143, in _get_response
    response = response.render()
  File "C:\Users\Sahil Arora\Desktop\SCP-B\venv\lib\site-packages\django\template\response.py", line 105, in render
    self.content = self.rendered_content
  File "C:\Users\Sahil Arora\Desktop\SCP-B\venv\lib\site-packages\django\template\response.py", line 83, in rendered_content
    return template.render(context, self._request)
  File "C:\Users\Sahil Arora\Desktop\SCP-B\venv\lib\site-packages\django\template\backends\django.py", line 61, in render
    return self.template.render(context)
  File "C:\Users\Sahil Arora\Desktop\SCP-B\venv\lib\site-packages\django\template\base.py", line 171, in render
    return self._render(context)
  File "C:\Users\Sahil Arora\Desktop\SCP-B\venv\lib\site-packages\django\template\base.py", line 163, in _render
    return self.nodelist.render(context)
  File "C:\Users\Sahil Arora\Desktop\SCP-B\venv\lib\site-packages\django\template\base.py", line 936, in render
    bit = node.render_annotated(context)
  File "C:\Users\Sahil Arora\Desktop\SCP-B\venv\lib\site-packages\django\template\base.py", line 903, in render_annotated
    return self.render(context)
  File "C:\Users\Sahil Arora\Desktop\SCP-B\venv\lib\site-packages\django\template\loader_tags.py", line 150, in render
    return compiled_parent._render(context)
  File "C:\Users\Sahil Arora\Desktop\SCP-B\venv\lib\site-packages\django\template\base.py", line 163, in _render
    return self.nodelist.render(context)
  File "C:\Users\Sahil Arora\Desktop\SCP-B\venv\lib\site-packages\django\template\base.py", line 936, in render
    bit = node.render_annotated(context)
  File "C:\Users\Sahil Arora\Desktop\SCP-B\venv\lib\site-packages\django\template\base.py", line 903, in render_annotated
    return self.render(context)
  File "C:\Users\Sahil Arora\Desktop\SCP-B\venv\lib\site-packages\django\template\loader_tags.py", line 150, in render
    return compiled_parent._render(context)
  File "C:\Users\Sahil Arora\Desktop\SCP-B\venv\lib\site-packages\django\template\base.py", line 163, in _render
    return self.nodelist.render(context)
  File "C:\Users\Sahil Arora\Desktop\SCP-B\venv\lib\site-packages\django\template\base.py", line 936, in render
    bit = node.render_annotated(context)
  File "C:\Users\Sahil Arora\Desktop\SCP-B\venv\lib\site-packages\django\template\base.py", line 903, in render_annotated
    return self.render(context)
  File "C:\Users\Sahil Arora\Desktop\SCP-B\venv\lib\site-packages\django\template\defaulttags.py", line 309, in render
    return nodelist.render(context)
  File "C:\Users\Sahil Arora\Desktop\SCP-B\venv\lib\site-packages\django\template\base.py", line 936, in render
    bit = node.render_annotated(context)
  File "C:\Users\Sahil Arora\Desktop\SCP-B\venv\lib\site-packages\django\template\base.py", line 903, in render_annotated
    return self.render(context)
  File "C:\Users\Sahil Arora\Desktop\SCP-B\venv\lib\site-packages\django\template\loader_tags.py", line 62, in render
    result = block.nodelist.render(context)
  File "C:\Users\Sahil Arora\Desktop\SCP-B\venv\lib\site-packages\django\template\base.py", line 936, in render
    bit = node.render_annotated(context)
  File "C:\Users\Sahil Arora\Desktop\SCP-B\venv\lib\site-packages\django\template\base.py", line 903, in render_annotated
    return self.render(context)
  File "C:\Users\Sahil Arora\Desktop\SCP-B\venv\lib\site-packages\django\template\defaulttags.py", line 309, in render
    return nodelist.render(context)
  File "C:\Users\Sahil Arora\Desktop\SCP-B\venv\lib\site-packages\django\template\base.py", line 936, in render
    bit = node.render_annotated(context)
  File "C:\Users\Sahil Arora\Desktop\SCP-B\venv\lib\site-packages\django\template\base.py", line 903, in render_annotated
    return self.render(context)
  File "C:\Users\Sahil Arora\Desktop\SCP-B\venv\lib\site-packages\django\template\base.py", line 986, in render
    output = self.filter_expression.resolve(context)
  File "C:\Users\Sahil Arora\Desktop\SCP-B\venv\lib\site-packages\django\template\base.py", line 697, in resolve
    new_obj = func(obj, *arg_vals)
  File "C:\Users\Sahil Arora\Desktop\SCP-B\venv\lib\site-packages\django\template\defaultfilters.py", line 42, in _dec
    args[0] = str(args[0])
TypeError: __str__ returned non-string (type int)
2020-09-24 08:44:58,890 ERROR    [log.py:228] Internal Server Error: /admin/SCPapp/emailverify/MT10201064/change/
Traceback (most recent call last):
  File "C:\Users\Sahil Arora\Desktop\SCP-B\venv\lib\site-packages\django\core\handlers\exception.py", line 34, in inner
    response = get_response(request)
  File "C:\Users\Sahil Arora\Desktop\SCP-B\venv\lib\site-packages\django\core\handlers\base.py", line 145, in _get_response
    response = self.process_exception_by_middleware(e, request)
  File "C:\Users\Sahil Arora\Desktop\SCP-B\venv\lib\site-packages\django\core\handlers\base.py", line 143, in _get_response
    response = response.render()
  File "C:\Users\Sahil Arora\Desktop\SCP-B\venv\lib\site-packages\django\template\response.py", line 105, in render
    self.content = self.rendered_content
  File "C:\Users\Sahil Arora\Desktop\SCP-B\venv\lib\site-packages\django\template\response.py", line 83, in rendered_content
    return template.render(context, self._request)
  File "C:\Users\Sahil Arora\Desktop\SCP-B\venv\lib\site-packages\django\template\backends\django.py", line 61, in render
    return self.template.render(context)
  File "C:\Users\Sahil Arora\Desktop\SCP-B\venv\lib\site-packages\django\template\base.py", line 171, in render
    return self._render(context)
  File "C:\Users\Sahil Arora\Desktop\SCP-B\venv\lib\site-packages\django\template\base.py", line 163, in _render
    return self.nodelist.render(context)
  File "C:\Users\Sahil Arora\Desktop\SCP-B\venv\lib\site-packages\django\template\base.py", line 936, in render
    bit = node.render_annotated(context)
  File "C:\Users\Sahil Arora\Desktop\SCP-B\venv\lib\site-packages\django\template\base.py", line 903, in render_annotated
    return self.render(context)
  File "C:\Users\Sahil Arora\Desktop\SCP-B\venv\lib\site-packages\django\template\loader_tags.py", line 150, in render
    return compiled_parent._render(context)
  File "C:\Users\Sahil Arora\Desktop\SCP-B\venv\lib\site-packages\django\template\base.py", line 163, in _render
    return self.nodelist.render(context)
  File "C:\Users\Sahil Arora\Desktop\SCP-B\venv\lib\site-packages\django\template\base.py", line 936, in render
    bit = node.render_annotated(context)
  File "C:\Users\Sahil Arora\Desktop\SCP-B\venv\lib\site-packages\django\template\base.py", line 903, in render_annotated
    return self.render(context)
  File "C:\Users\Sahil Arora\Desktop\SCP-B\venv\lib\site-packages\django\template\loader_tags.py", line 150, in render
    return compiled_parent._render(context)
  File "C:\Users\Sahil Arora\Desktop\SCP-B\venv\lib\site-packages\django\template\base.py", line 163, in _render
    return self.nodelist.render(context)
  File "C:\Users\Sahil Arora\Desktop\SCP-B\venv\lib\site-packages\django\template\base.py", line 936, in render
    bit = node.render_annotated(context)
  File "C:\Users\Sahil Arora\Desktop\SCP-B\venv\lib\site-packages\django\template\base.py", line 903, in render_annotated
    return self.render(context)
  File "C:\Users\Sahil Arora\Desktop\SCP-B\venv\lib\site-packages\django\template\defaulttags.py", line 309, in render
    return nodelist.render(context)
  File "C:\Users\Sahil Arora\Desktop\SCP-B\venv\lib\site-packages\django\template\base.py", line 936, in render
    bit = node.render_annotated(context)
  File "C:\Users\Sahil Arora\Desktop\SCP-B\venv\lib\site-packages\django\template\base.py", line 903, in render_annotated
    return self.render(context)
  File "C:\Users\Sahil Arora\Desktop\SCP-B\venv\lib\site-packages\django\template\loader_tags.py", line 62, in render
    result = block.nodelist.render(context)
  File "C:\Users\Sahil Arora\Desktop\SCP-B\venv\lib\site-packages\django\template\base.py", line 936, in render
    bit = node.render_annotated(context)
  File "C:\Users\Sahil Arora\Desktop\SCP-B\venv\lib\site-packages\django\template\base.py", line 903, in render_annotated
    return self.render(context)
  File "C:\Users\Sahil Arora\Desktop\SCP-B\venv\lib\site-packages\django\template\defaulttags.py", line 309, in render
    return nodelist.render(context)
  File "C:\Users\Sahil Arora\Desktop\SCP-B\venv\lib\site-packages\django\template\base.py", line 936, in render
    bit = node.render_annotated(context)
  File "C:\Users\Sahil Arora\Desktop\SCP-B\venv\lib\site-packages\django\template\base.py", line 903, in render_annotated
    return self.render(context)
  File "C:\Users\Sahil Arora\Desktop\SCP-B\venv\lib\site-packages\django\template\base.py", line 986, in render
    output = self.filter_expression.resolve(context)
  File "C:\Users\Sahil Arora\Desktop\SCP-B\venv\lib\site-packages\django\template\base.py", line 697, in resolve
    new_obj = func(obj, *arg_vals)
  File "C:\Users\Sahil Arora\Desktop\SCP-B\venv\lib\site-packages\django\template\defaultfilters.py", line 42, in _dec
    args[0] = str(args[0])
TypeError: __str__ returned non-string (type int)
2020-09-24 08:45:05,832 ERROR    [log.py:228] Internal Server Error: /admin/SCPapp/emailverify/MT10201067/change/
Traceback (most recent call last):
  File "C:\Users\Sahil Arora\Desktop\SCP-B\venv\lib\site-packages\django\core\handlers\exception.py", line 34, in inner
    response = get_response(request)
  File "C:\Users\Sahil Arora\Desktop\SCP-B\venv\lib\site-packages\django\core\handlers\base.py", line 145, in _get_response
    response = self.process_exception_by_middleware(e, request)
  File "C:\Users\Sahil Arora\Desktop\SCP-B\venv\lib\site-packages\django\core\handlers\base.py", line 143, in _get_response
    response = response.render()
  File "C:\Users\Sahil Arora\Desktop\SCP-B\venv\lib\site-packages\django\template\response.py", line 105, in render
    self.content = self.rendered_content
  File "C:\Users\Sahil Arora\Desktop\SCP-B\venv\lib\site-packages\django\template\response.py", line 83, in rendered_content
    return template.render(context, self._request)
  File "C:\Users\Sahil Arora\Desktop\SCP-B\venv\lib\site-packages\django\template\backends\django.py", line 61, in render
    return self.template.render(context)
  File "C:\Users\Sahil Arora\Desktop\SCP-B\venv\lib\site-packages\django\template\base.py", line 171, in render
    return self._render(context)
  File "C:\Users\Sahil Arora\Desktop\SCP-B\venv\lib\site-packages\django\template\base.py", line 163, in _render
    return self.nodelist.render(context)
  File "C:\Users\Sahil Arora\Desktop\SCP-B\venv\lib\site-packages\django\template\base.py", line 936, in render
    bit = node.render_annotated(context)
  File "C:\Users\Sahil Arora\Desktop\SCP-B\venv\lib\site-packages\django\template\base.py", line 903, in render_annotated
    return self.render(context)
  File "C:\Users\Sahil Arora\Desktop\SCP-B\venv\lib\site-packages\django\template\loader_tags.py", line 150, in render
    return compiled_parent._render(context)
  File "C:\Users\Sahil Arora\Desktop\SCP-B\venv\lib\site-packages\django\template\base.py", line 163, in _render
    return self.nodelist.render(context)
  File "C:\Users\Sahil Arora\Desktop\SCP-B\venv\lib\site-packages\django\template\base.py", line 936, in render
    bit = node.render_annotated(context)
  File "C:\Users\Sahil Arora\Desktop\SCP-B\venv\lib\site-packages\django\template\base.py", line 903, in render_annotated
    return self.render(context)
  File "C:\Users\Sahil Arora\Desktop\SCP-B\venv\lib\site-packages\django\template\loader_tags.py", line 150, in render
    return compiled_parent._render(context)
  File "C:\Users\Sahil Arora\Desktop\SCP-B\venv\lib\site-packages\django\template\base.py", line 163, in _render
    return self.nodelist.render(context)
  File "C:\Users\Sahil Arora\Desktop\SCP-B\venv\lib\site-packages\django\template\base.py", line 936, in render
    bit = node.render_annotated(context)
  File "C:\Users\Sahil Arora\Desktop\SCP-B\venv\lib\site-packages\django\template\base.py", line 903, in render_annotated
    return self.render(context)
  File "C:\Users\Sahil Arora\Desktop\SCP-B\venv\lib\site-packages\django\template\defaulttags.py", line 309, in render
    return nodelist.render(context)
  File "C:\Users\Sahil Arora\Desktop\SCP-B\venv\lib\site-packages\django\template\base.py", line 936, in render
    bit = node.render_annotated(context)
  File "C:\Users\Sahil Arora\Desktop\SCP-B\venv\lib\site-packages\django\template\base.py", line 903, in render_annotated
    return self.render(context)
  File "C:\Users\Sahil Arora\Desktop\SCP-B\venv\lib\site-packages\django\template\loader_tags.py", line 62, in render
    result = block.nodelist.render(context)
  File "C:\Users\Sahil Arora\Desktop\SCP-B\venv\lib\site-packages\django\template\base.py", line 936, in render
    bit = node.render_annotated(context)
  File "C:\Users\Sahil Arora\Desktop\SCP-B\venv\lib\site-packages\django\template\base.py", line 903, in render_annotated
    return self.render(context)
  File "C:\Users\Sahil Arora\Desktop\SCP-B\venv\lib\site-packages\django\template\defaulttags.py", line 309, in render
    return nodelist.render(context)
  File "C:\Users\Sahil Arora\Desktop\SCP-B\venv\lib\site-packages\django\template\base.py", line 936, in render
    bit = node.render_annotated(context)
  File "C:\Users\Sahil Arora\Desktop\SCP-B\venv\lib\site-packages\django\template\base.py", line 903, in render_annotated
    return self.render(context)
  File "C:\Users\Sahil Arora\Desktop\SCP-B\venv\lib\site-packages\django\template\base.py", line 986, in render
    output = self.filter_expression.resolve(context)
  File "C:\Users\Sahil Arora\Desktop\SCP-B\venv\lib\site-packages\django\template\base.py", line 697, in resolve
    new_obj = func(obj, *arg_vals)
  File "C:\Users\Sahil Arora\Desktop\SCP-B\venv\lib\site-packages\django\template\defaultfilters.py", line 42, in _dec
    args[0] = str(args[0])
TypeError: __str__ returned non-string (type int)
2020-09-24 08:46:36,486 WARNING  [log.py:228] Not Found: /verifyEmailID/
2020-09-24 08:48:17,740 WARNING  [log.py:228] Not Found: /verifyEmailID/
2020-09-24 08:51:13,387 WARNING  [log.py:228] Not Found: /verifyEmailID/
2020-09-24 08:54:56,219 WARNING  [log.py:228] Not Found: /verifyEmailID/
2020-09-24 08:57:18,599 WARNING  [log.py:228] Not Found: /verifyEmailID/
2020-09-24 08:57:28,447 WARNING  [log.py:228] Not Found: /verifyEmailID/
2020-09-24 12:49:50,803 WARNING  [log.py:228] Not Found: /verifyEmailID/
2020-09-24 12:51:18,60 ERROR    [log.py:228] Internal Server Error: /verifyEmailID/
Traceback (most recent call last):
  File "C:\Users\Sahil Arora\Desktop\SCP-B\venv\lib\site-packages\django\db\models\fields\__init__.py", line 1772, in get_prep_value
    return int(value)
ValueError: invalid literal for int() with base 10: ''

The above exception was the direct cause of the following exception:

Traceback (most recent call last):
  File "C:\Users\Sahil Arora\Desktop\SCP-B\venv\lib\site-packages\django\core\handlers\exception.py", line 34, in inner
    response = get_response(request)
  File "C:\Users\Sahil Arora\Desktop\SCP-B\venv\lib\site-packages\django\core\handlers\base.py", line 115, in _get_response
    response = self.process_exception_by_middleware(e, request)
  File "C:\Users\Sahil Arora\Desktop\SCP-B\venv\lib\site-packages\django\core\handlers\base.py", line 113, in _get_response
    response = wrapped_callback(request, *callback_args, **callback_kwargs)
  File "C:\Users\Sahil Arora\Desktop\SCP-B\venv\lib\site-packages\django\views\decorators\csrf.py", line 54, in wrapped_view
    return view_func(*args, **kwargs)
  File "C:\Users\Sahil Arora\Desktop\SCP-B\venv\lib\site-packages\django\views\generic\base.py", line 71, in view
    return self.dispatch(request, *args, **kwargs)
  File "C:\Users\Sahil Arora\Desktop\SCP-B\venv\lib\site-packages\rest_framework\views.py", line 505, in dispatch
    response = self.handle_exception(exc)
  File "C:\Users\Sahil Arora\Desktop\SCP-B\venv\lib\site-packages\rest_framework\views.py", line 465, in handle_exception
    self.raise_uncaught_exception(exc)
  File "C:\Users\Sahil Arora\Desktop\SCP-B\venv\lib\site-packages\rest_framework\views.py", line 476, in raise_uncaught_exception
    raise exc
  File "C:\Users\Sahil Arora\Desktop\SCP-B\venv\lib\site-packages\rest_framework\views.py", line 502, in dispatch
    response = handler(request, *args, **kwargs)
  File "C:\Users\Sahil Arora\Desktop\SCP-B\SCP-backened\SCPapp\views.py", line 65, in post
    emailVerify = self.get_object(request.data["otp"])
  File "C:\Users\Sahil Arora\Desktop\SCP-B\SCP-backened\SCPapp\views.py", line 59, in get_object
    return emailVerify.objects.get(otp=otp)
  File "C:\Users\Sahil Arora\Desktop\SCP-B\venv\lib\site-packages\django\db\models\manager.py", line 82, in manager_method
    return getattr(self.get_queryset(), name)(*args, **kwargs)
  File "C:\Users\Sahil Arora\Desktop\SCP-B\venv\lib\site-packages\django\db\models\query.py", line 404, in get
    clone = self._chain() if self.query.combinator else self.filter(*args, **kwargs)
  File "C:\Users\Sahil Arora\Desktop\SCP-B\venv\lib\site-packages\django\db\models\query.py", line 904, in filter
    return self._filter_or_exclude(False, *args, **kwargs)
  File "C:\Users\Sahil Arora\Desktop\SCP-B\venv\lib\site-packages\django\db\models\query.py", line 923, in _filter_or_exclude
    clone.query.add_q(Q(*args, **kwargs))
  File "C:\Users\Sahil Arora\Desktop\SCP-B\venv\lib\site-packages\django\db\models\sql\query.py", line 1350, in add_q
    clause, _ = self._add_q(q_object, self.used_aliases)
  File "C:\Users\Sahil Arora\Desktop\SCP-B\venv\lib\site-packages\django\db\models\sql\query.py", line 1381, in _add_q
    check_filterable=check_filterable,
  File "C:\Users\Sahil Arora\Desktop\SCP-B\venv\lib\site-packages\django\db\models\sql\query.py", line 1311, in build_filter
    condition = self.build_lookup(lookups, col, value)
  File "C:\Users\Sahil Arora\Desktop\SCP-B\venv\lib\site-packages\django\db\models\sql\query.py", line 1165, in build_lookup
    lookup = lookup_class(lhs, rhs)
  File "C:\Users\Sahil Arora\Desktop\SCP-B\venv\lib\site-packages\django\db\models\lookups.py", line 22, in __init__
    self.rhs = self.get_prep_lookup()
  File "C:\Users\Sahil Arora\Desktop\SCP-B\venv\lib\site-packages\django\db\models\lookups.py", line 72, in get_prep_lookup
    return self.lhs.output_field.get_prep_value(self.rhs)
  File "C:\Users\Sahil Arora\Desktop\SCP-B\venv\lib\site-packages\django\db\models\fields\__init__.py", line 1776, in get_prep_value
    ) from e
ValueError: Field 'otp' expected a number but got ''.
2020-09-24 12:54:17,903 WARNING  [log.py:228] Not Found: /verifyEmailID/
2020-09-24 12:56:21,870 ERROR    [log.py:228] Internal Server Error: /verifyEmailID/
Traceback (most recent call last):
  File "C:\Users\Sahil Arora\Desktop\SCP-B\venv\lib\site-packages\django\core\handlers\exception.py", line 34, in inner
    response = get_response(request)
  File "C:\Users\Sahil Arora\Desktop\SCP-B\venv\lib\site-packages\django\core\handlers\base.py", line 115, in _get_response
    response = self.process_exception_by_middleware(e, request)
  File "C:\Users\Sahil Arora\Desktop\SCP-B\venv\lib\site-packages\django\core\handlers\base.py", line 113, in _get_response
    response = wrapped_callback(request, *callback_args, **callback_kwargs)
  File "C:\Users\Sahil Arora\Desktop\SCP-B\venv\lib\site-packages\django\views\decorators\csrf.py", line 54, in wrapped_view
    return view_func(*args, **kwargs)
  File "C:\Users\Sahil Arora\Desktop\SCP-B\venv\lib\site-packages\django\views\generic\base.py", line 71, in view
    return self.dispatch(request, *args, **kwargs)
  File "C:\Users\Sahil Arora\Desktop\SCP-B\venv\lib\site-packages\rest_framework\views.py", line 505, in dispatch
    response = self.handle_exception(exc)
  File "C:\Users\Sahil Arora\Desktop\SCP-B\venv\lib\site-packages\rest_framework\views.py", line 465, in handle_exception
    self.raise_uncaught_exception(exc)
  File "C:\Users\Sahil Arora\Desktop\SCP-B\venv\lib\site-packages\rest_framework\views.py", line 476, in raise_uncaught_exception
    raise exc
  File "C:\Users\Sahil Arora\Desktop\SCP-B\venv\lib\site-packages\rest_framework\views.py", line 502, in dispatch
    response = handler(request, *args, **kwargs)
  File "C:\Users\Sahil Arora\Desktop\SCP-B\SCP-backened\SCPapp\views.py", line 65, in post
    emailVerify = self.get_object(request.data["otp"])
KeyError: 'otp'
2020-09-24 12:57:18,246 ERROR    [log.py:228] Internal Server Error: /verifyEmailID/
Traceback (most recent call last):
  File "C:\Users\Sahil Arora\Desktop\SCP-B\venv\lib\site-packages\django\core\handlers\exception.py", line 34, in inner
    response = get_response(request)
  File "C:\Users\Sahil Arora\Desktop\SCP-B\venv\lib\site-packages\django\core\handlers\base.py", line 115, in _get_response
    response = self.process_exception_by_middleware(e, request)
  File "C:\Users\Sahil Arora\Desktop\SCP-B\venv\lib\site-packages\django\core\handlers\base.py", line 113, in _get_response
    response = wrapped_callback(request, *callback_args, **callback_kwargs)
  File "C:\Users\Sahil Arora\Desktop\SCP-B\venv\lib\site-packages\django\views\decorators\csrf.py", line 54, in wrapped_view
    return view_func(*args, **kwargs)
  File "C:\Users\Sahil Arora\Desktop\SCP-B\venv\lib\site-packages\django\views\generic\base.py", line 71, in view
    return self.dispatch(request, *args, **kwargs)
  File "C:\Users\Sahil Arora\Desktop\SCP-B\venv\lib\site-packages\rest_framework\views.py", line 505, in dispatch
    response = self.handle_exception(exc)
  File "C:\Users\Sahil Arora\Desktop\SCP-B\venv\lib\site-packages\rest_framework\views.py", line 465, in handle_exception
    self.raise_uncaught_exception(exc)
  File "C:\Users\Sahil Arora\Desktop\SCP-B\venv\lib\site-packages\rest_framework\views.py", line 476, in raise_uncaught_exception
    raise exc
  File "C:\Users\Sahil Arora\Desktop\SCP-B\venv\lib\site-packages\rest_framework\views.py", line 502, in dispatch
    response = handler(request, *args, **kwargs)
  File "C:\Users\Sahil Arora\Desktop\SCP-B\SCP-backened\SCPapp\views.py", line 65, in post
    emailVerify = self.get_object(request.data["otp"])
KeyError: 'otp'
2020-09-24 13:00:29,526 WARNING  [log.py:228] Not Found: /verifyEmailID/
2020-09-24 13:04:33,966 WARNING  [log.py:228] Not Found: /verifyEmailID/
2020-09-24 13:06:27,366 WARNING  [log.py:228] Not Found: /verifyEmailID/
2020-09-24 13:06:33,251 WARNING  [log.py:228] Not Found: /verifyEmailID/
2020-09-24 13:08:22,100 WARNING  [log.py:228] Not Found: /verifyEmailID/
2020-09-24 13:08:26,441 ERROR    [log.py:228] Internal Server Error: /verifyEmailID/
Traceback (most recent call last):
  File "C:\Users\Sahil Arora\Desktop\SCP-B\venv\lib\site-packages\django\db\models\fields\__init__.py", line 1772, in get_prep_value
    return int(value)
ValueError: invalid literal for int() with base 10: '666j'

The above exception was the direct cause of the following exception:

Traceback (most recent call last):
  File "C:\Users\Sahil Arora\Desktop\SCP-B\venv\lib\site-packages\django\core\handlers\exception.py", line 34, in inner
    response = get_response(request)
  File "C:\Users\Sahil Arora\Desktop\SCP-B\venv\lib\site-packages\django\core\handlers\base.py", line 115, in _get_response
    response = self.process_exception_by_middleware(e, request)
  File "C:\Users\Sahil Arora\Desktop\SCP-B\venv\lib\site-packages\django\core\handlers\base.py", line 113, in _get_response
    response = wrapped_callback(request, *callback_args, **callback_kwargs)
  File "C:\Users\Sahil Arora\Desktop\SCP-B\venv\lib\site-packages\django\views\decorators\csrf.py", line 54, in wrapped_view
    return view_func(*args, **kwargs)
  File "C:\Users\Sahil Arora\Desktop\SCP-B\venv\lib\site-packages\django\views\generic\base.py", line 71, in view
    return self.dispatch(request, *args, **kwargs)
  File "C:\Users\Sahil Arora\Desktop\SCP-B\venv\lib\site-packages\rest_framework\views.py", line 505, in dispatch
    response = self.handle_exception(exc)
  File "C:\Users\Sahil Arora\Desktop\SCP-B\venv\lib\site-packages\rest_framework\views.py", line 465, in handle_exception
    self.raise_uncaught_exception(exc)
  File "C:\Users\Sahil Arora\Desktop\SCP-B\venv\lib\site-packages\rest_framework\views.py", line 476, in raise_uncaught_exception
    raise exc
  File "C:\Users\Sahil Arora\Desktop\SCP-B\venv\lib\site-packages\rest_framework\views.py", line 502, in dispatch
    response = handler(request, *args, **kwargs)
  File "C:\Users\Sahil Arora\Desktop\SCP-B\SCP-backened\SCPapp\views.py", line 65, in post
    emailVerify = self.get_object(request.data["otp"])
  File "C:\Users\Sahil Arora\Desktop\SCP-B\SCP-backened\SCPapp\views.py", line 59, in get_object
    return emailVerify.objects.get(otp=otp)
  File "C:\Users\Sahil Arora\Desktop\SCP-B\venv\lib\site-packages\django\db\models\manager.py", line 82, in manager_method
    return getattr(self.get_queryset(), name)(*args, **kwargs)
  File "C:\Users\Sahil Arora\Desktop\SCP-B\venv\lib\site-packages\django\db\models\query.py", line 404, in get
    clone = self._chain() if self.query.combinator else self.filter(*args, **kwargs)
  File "C:\Users\Sahil Arora\Desktop\SCP-B\venv\lib\site-packages\django\db\models\query.py", line 904, in filter
    return self._filter_or_exclude(False, *args, **kwargs)
  File "C:\Users\Sahil Arora\Desktop\SCP-B\venv\lib\site-packages\django\db\models\query.py", line 923, in _filter_or_exclude
    clone.query.add_q(Q(*args, **kwargs))
  File "C:\Users\Sahil Arora\Desktop\SCP-B\venv\lib\site-packages\django\db\models\sql\query.py", line 1350, in add_q
    clause, _ = self._add_q(q_object, self.used_aliases)
  File "C:\Users\Sahil Arora\Desktop\SCP-B\venv\lib\site-packages\django\db\models\sql\query.py", line 1381, in _add_q
    check_filterable=check_filterable,
  File "C:\Users\Sahil Arora\Desktop\SCP-B\venv\lib\site-packages\django\db\models\sql\query.py", line 1311, in build_filter
    condition = self.build_lookup(lookups, col, value)
  File "C:\Users\Sahil Arora\Desktop\SCP-B\venv\lib\site-packages\django\db\models\sql\query.py", line 1165, in build_lookup
    lookup = lookup_class(lhs, rhs)
  File "C:\Users\Sahil Arora\Desktop\SCP-B\venv\lib\site-packages\django\db\models\lookups.py", line 22, in __init__
    self.rhs = self.get_prep_lookup()
  File "C:\Users\Sahil Arora\Desktop\SCP-B\venv\lib\site-packages\django\db\models\lookups.py", line 72, in get_prep_lookup
    return self.lhs.output_field.get_prep_value(self.rhs)
  File "C:\Users\Sahil Arora\Desktop\SCP-B\venv\lib\site-packages\django\db\models\fields\__init__.py", line 1776, in get_prep_value
    ) from e
ValueError: Field 'otp' expected a number but got '666j'.
2020-09-24 13:11:26,178 WARNING  [log.py:228] Not Found: /verifyEmailID/
2020-09-24 13:16:20,344 ERROR    [log.py:228] Internal Server Error: /confirmEmailID/
Traceback (most recent call last):
  File "C:\Users\Sahil Arora\Desktop\SCP-B\venv\lib\site-packages\django\core\handlers\exception.py", line 34, in inner
    response = get_response(request)
  File "C:\Users\Sahil Arora\Desktop\SCP-B\venv\lib\site-packages\django\core\handlers\base.py", line 145, in _get_response
    response = self.process_exception_by_middleware(e, request)
  File "C:\Users\Sahil Arora\Desktop\SCP-B\venv\lib\site-packages\django\core\handlers\base.py", line 143, in _get_response
    response = response.render()
  File "C:\Users\Sahil Arora\Desktop\SCP-B\venv\lib\site-packages\django\template\response.py", line 105, in render
    self.content = self.rendered_content
  File "C:\Users\Sahil Arora\Desktop\SCP-B\venv\lib\site-packages\rest_framework\response.py", line 70, in rendered_content
    ret = renderer.render(self.data, accepted_media_type, context)
  File "C:\Users\Sahil Arora\Desktop\SCP-B\venv\lib\site-packages\rest_framework\renderers.py", line 103, in render
    allow_nan=not self.strict, separators=separators
  File "C:\Users\Sahil Arora\Desktop\SCP-B\venv\lib\site-packages\rest_framework\utils\json.py", line 25, in dumps
    return json.dumps(*args, **kwargs)
  File "C:\Users\Sahil Arora\AppData\Local\Programs\Python\Python36\lib\json\__init__.py", line 238, in dumps
    **kw).encode(obj)
  File "C:\Users\Sahil Arora\AppData\Local\Programs\Python\Python36\lib\json\encoder.py", line 199, in encode
    chunks = self.iterencode(o, _one_shot=True)
  File "C:\Users\Sahil Arora\AppData\Local\Programs\Python\Python36\lib\json\encoder.py", line 257, in iterencode
    return _iterencode(o, 0)
  File "C:\Users\Sahil Arora\Desktop\SCP-B\venv\lib\site-packages\rest_framework\utils\encoders.py", line 67, in default
    return super().default(obj)
  File "C:\Users\Sahil Arora\AppData\Local\Programs\Python\Python36\lib\json\encoder.py", line 180, in default
    o.__class__.__name__)
TypeError: Object of type 'property' is not JSON serializable
2020-09-24 13:34:27,948 ERROR    [log.py:228] Internal Server Error: /confirmEmailID/
Traceback (most recent call last):
  File "C:\Users\Sahil Arora\Desktop\SCP-B\venv\lib\site-packages\django\core\handlers\exception.py", line 34, in inner
    response = get_response(request)
  File "C:\Users\Sahil Arora\Desktop\SCP-B\venv\lib\site-packages\django\core\handlers\base.py", line 115, in _get_response
    response = self.process_exception_by_middleware(e, request)
  File "C:\Users\Sahil Arora\Desktop\SCP-B\venv\lib\site-packages\django\core\handlers\base.py", line 113, in _get_response
    response = wrapped_callback(request, *callback_args, **callback_kwargs)
  File "C:\Users\Sahil Arora\Desktop\SCP-B\venv\lib\site-packages\django\views\decorators\csrf.py", line 54, in wrapped_view
    return view_func(*args, **kwargs)
  File "C:\Users\Sahil Arora\Desktop\SCP-B\venv\lib\site-packages\django\views\generic\base.py", line 71, in view
    return self.dispatch(request, *args, **kwargs)
  File "C:\Users\Sahil Arora\Desktop\SCP-B\venv\lib\site-packages\rest_framework\views.py", line 505, in dispatch
    response = self.handle_exception(exc)
  File "C:\Users\Sahil Arora\Desktop\SCP-B\venv\lib\site-packages\rest_framework\views.py", line 465, in handle_exception
    self.raise_uncaught_exception(exc)
  File "C:\Users\Sahil Arora\Desktop\SCP-B\venv\lib\site-packages\rest_framework\views.py", line 476, in raise_uncaught_exception
    raise exc
  File "C:\Users\Sahil Arora\Desktop\SCP-B\venv\lib\site-packages\rest_framework\views.py", line 502, in dispatch
    response = handler(request, *args, **kwargs)
  File "C:\Users\Sahil Arora\Desktop\SCP-B\SCP-backened\SCPapp\views.py", line 38, in post
    [request.data["email"]], fail_silently=False, )
  File "C:\Users\Sahil Arora\Desktop\SCP-B\venv\lib\site-packages\django\core\mail\__init__.py", line 60, in send_mail
    return mail.send()
  File "C:\Users\Sahil Arora\Desktop\SCP-B\venv\lib\site-packages\django\core\mail\message.py", line 276, in send
    return self.get_connection(fail_silently).send_messages([self])
  File "C:\Users\Sahil Arora\Desktop\SCP-B\venv\lib\site-packages\django\core\mail\backends\smtp.py", line 109, in send_messages
    sent = self._send(message)
  File "C:\Users\Sahil Arora\Desktop\SCP-B\venv\lib\site-packages\django\core\mail\backends\smtp.py", line 125, in _send
    self.connection.sendmail(from_email, recipients, message.as_bytes(linesep='\r\n'))
  File "C:\Users\Sahil Arora\AppData\Local\Programs\Python\Python36\lib\smtplib.py", line 881, in sendmail
    raise SMTPRecipientsRefused(senderrs)
smtplib.SMTPRecipientsRefused: {'ggg': (553, b'5.1.3 The recipient address <ggg> is not a valid RFC-5321 address. q15sm2184675pgr.27 - gsmtp')}
2020-09-24 13:37:05,947 WARNING  [log.py:228] Not Found: /verifyEmailID/
2020-09-24 13:37:37,447 ERROR    [log.py:228] Internal Server Error: /confirmEmailID/
Traceback (most recent call last):
  File "C:\Users\Sahil Arora\Desktop\SCP-B\venv\lib\site-packages\django\core\handlers\exception.py", line 34, in inner
    response = get_response(request)
  File "C:\Users\Sahil Arora\Desktop\SCP-B\venv\lib\site-packages\django\core\handlers\base.py", line 145, in _get_response
    response = self.process_exception_by_middleware(e, request)
  File "C:\Users\Sahil Arora\Desktop\SCP-B\venv\lib\site-packages\django\core\handlers\base.py", line 143, in _get_response
    response = response.render()
  File "C:\Users\Sahil Arora\Desktop\SCP-B\venv\lib\site-packages\django\template\response.py", line 105, in render
    self.content = self.rendered_content
  File "C:\Users\Sahil Arora\Desktop\SCP-B\venv\lib\site-packages\rest_framework\response.py", line 70, in rendered_content
    ret = renderer.render(self.data, accepted_media_type, context)
  File "C:\Users\Sahil Arora\Desktop\SCP-B\venv\lib\site-packages\rest_framework\renderers.py", line 103, in render
    allow_nan=not self.strict, separators=separators
  File "C:\Users\Sahil Arora\Desktop\SCP-B\venv\lib\site-packages\rest_framework\utils\json.py", line 25, in dumps
    return json.dumps(*args, **kwargs)
  File "C:\Users\Sahil Arora\AppData\Local\Programs\Python\Python36\lib\json\__init__.py", line 238, in dumps
    **kw).encode(obj)
  File "C:\Users\Sahil Arora\AppData\Local\Programs\Python\Python36\lib\json\encoder.py", line 199, in encode
    chunks = self.iterencode(o, _one_shot=True)
  File "C:\Users\Sahil Arora\AppData\Local\Programs\Python\Python36\lib\json\encoder.py", line 257, in iterencode
    return _iterencode(o, 0)
  File "C:\Users\Sahil Arora\Desktop\SCP-B\venv\lib\site-packages\rest_framework\utils\encoders.py", line 67, in default
    return super().default(obj)
  File "C:\Users\Sahil Arora\AppData\Local\Programs\Python\Python36\lib\json\encoder.py", line 180, in default
    o.__class__.__name__)
TypeError: Object of type 'property' is not JSON serializable
2020-09-24 13:40:45,611 ERROR    [log.py:228] Internal Server Error: /confirmEmailID/
Traceback (most recent call last):
  File "C:\Users\Sahil Arora\Desktop\SCP-B\venv\lib\site-packages\django\core\handlers\exception.py", line 34, in inner
    response = get_response(request)
  File "C:\Users\Sahil Arora\Desktop\SCP-B\venv\lib\site-packages\django\core\handlers\base.py", line 145, in _get_response
    response = self.process_exception_by_middleware(e, request)
  File "C:\Users\Sahil Arora\Desktop\SCP-B\venv\lib\site-packages\django\core\handlers\base.py", line 143, in _get_response
    response = response.render()
  File "C:\Users\Sahil Arora\Desktop\SCP-B\venv\lib\site-packages\django\template\response.py", line 105, in render
    self.content = self.rendered_content
  File "C:\Users\Sahil Arora\Desktop\SCP-B\venv\lib\site-packages\rest_framework\response.py", line 70, in rendered_content
    ret = renderer.render(self.data, accepted_media_type, context)
  File "C:\Users\Sahil Arora\Desktop\SCP-B\venv\lib\site-packages\rest_framework\renderers.py", line 103, in render
    allow_nan=not self.strict, separators=separators
  File "C:\Users\Sahil Arora\Desktop\SCP-B\venv\lib\site-packages\rest_framework\utils\json.py", line 25, in dumps
    return json.dumps(*args, **kwargs)
  File "C:\Users\Sahil Arora\AppData\Local\Programs\Python\Python36\lib\json\__init__.py", line 238, in dumps
    **kw).encode(obj)
  File "C:\Users\Sahil Arora\AppData\Local\Programs\Python\Python36\lib\json\encoder.py", line 199, in encode
    chunks = self.iterencode(o, _one_shot=True)
  File "C:\Users\Sahil Arora\AppData\Local\Programs\Python\Python36\lib\json\encoder.py", line 257, in iterencode
    return _iterencode(o, 0)
  File "C:\Users\Sahil Arora\Desktop\SCP-B\venv\lib\site-packages\rest_framework\utils\encoders.py", line 67, in default
    return super().default(obj)
  File "C:\Users\Sahil Arora\AppData\Local\Programs\Python\Python36\lib\json\encoder.py", line 180, in default
    o.__class__.__name__)
TypeError: Object of type 'property' is not JSON serializable
2020-09-24 13:48:00,504 INFO     [views.py:102] Trying: GET: User data by rollNumber MT2019123
2020-09-24 13:48:00,575 WARNING  [log.py:228] Not Found: /loginData/MT2019123/
2020-09-24 13:48:14,486 INFO     [views.py:102] Trying: GET: User data by rollNumber MT2019123
2020-09-24 13:48:14,498 WARNING  [log.py:228] Not Found: /loginData/MT2019123/
2020-09-24 13:51:27,991 INFO     [autoreload.py:222] C:\Users\Sahil Arora\Desktop\SCP-B\SCP-backened\SCPapp\views.py changed, reloading.
2020-09-24 13:55:35,758 WARNING  [log.py:228] Method Not Allowed: /loginData/create/
2020-09-24 13:57:19,200 INFO     [views.py:86] Trying: POST: User Registration data..
2020-09-24 13:57:19,261 ERROR    [views.py:93] Failed: POST: to save User Register data.. 400
2020-09-24 13:57:19,263 WARNING  [log.py:228] Bad Request: /loginData/
2020-09-24 13:58:50,173 INFO     [views.py:86] Trying: POST: User Registration data..
2020-09-24 13:58:50,187 ERROR    [views.py:93] Failed: POST: to save User Register data.. 400
2020-09-24 13:58:50,189 WARNING  [log.py:228] Bad Request: /loginData/
2020-09-24 13:59:16,516 INFO     [views.py:86] Trying: POST: User Registration data..
2020-09-24 13:59:16,570 INFO     [views.py:90] Successful: POST: User got saved.. 201 
2020-09-24 14:00:31,688 INFO     [views.py:86] Trying: POST: User Registration data..
2020-09-24 14:00:31,741 INFO     [views.py:90] Successful: POST: User got saved.. 201 
2020-09-24 14:00:55,698 INFO     [views.py:78] Trying to get User Login Data....
2020-09-24 14:00:55,699 INFO     [views.py:81] Successfully got the User Login Data  201
2020-09-24 14:01:23,535 INFO     [views.py:101] Trying: GET: User data by rollNumber MT20191123
2020-09-24 14:01:23,545 INFO     [views.py:111] Successful: GET: User data by rollNumber MT20191123
2020-09-24 14:02:10,142 INFO     [views.py:86] Trying: POST: User Registration data..
2020-09-24 14:02:10,191 INFO     [views.py:90] Successful: POST: User got saved.. 201 
2020-09-24 14:07:18,305 WARNING  [log.py:228] Not Found: /verifyEmailID/
2020-09-24 14:09:06,799 WARNING  [log.py:228] Not Found: /verifyEmailID/
2020-09-24 14:09:34,887 INFO     [views.py:86] Trying: POST: User Registration data..
2020-09-24 14:09:34,904 INFO     [views.py:90] Successful: POST: User got saved.. 201 
2020-09-24 14:43:41,98 WARNING  [log.py:228] Not Found: /verifyEmailID/
2020-09-24 14:43:58,821 ERROR    [log.py:228] Internal Server Error: /confirmEmailID/
Traceback (most recent call last):
  File "C:\Users\Sahil Arora\Desktop\SCP-B\venv\lib\site-packages\django\core\handlers\exception.py", line 34, in inner
    response = get_response(request)
  File "C:\Users\Sahil Arora\Desktop\SCP-B\venv\lib\site-packages\django\core\handlers\base.py", line 145, in _get_response
    response = self.process_exception_by_middleware(e, request)
  File "C:\Users\Sahil Arora\Desktop\SCP-B\venv\lib\site-packages\django\core\handlers\base.py", line 143, in _get_response
    response = response.render()
  File "C:\Users\Sahil Arora\Desktop\SCP-B\venv\lib\site-packages\django\template\response.py", line 105, in render
    self.content = self.rendered_content
  File "C:\Users\Sahil Arora\Desktop\SCP-B\venv\lib\site-packages\rest_framework\response.py", line 70, in rendered_content
    ret = renderer.render(self.data, accepted_media_type, context)
  File "C:\Users\Sahil Arora\Desktop\SCP-B\venv\lib\site-packages\rest_framework\renderers.py", line 103, in render
    allow_nan=not self.strict, separators=separators
  File "C:\Users\Sahil Arora\Desktop\SCP-B\venv\lib\site-packages\rest_framework\utils\json.py", line 25, in dumps
    return json.dumps(*args, **kwargs)
  File "C:\Users\Sahil Arora\AppData\Local\Programs\Python\Python36\lib\json\__init__.py", line 238, in dumps
    **kw).encode(obj)
  File "C:\Users\Sahil Arora\AppData\Local\Programs\Python\Python36\lib\json\encoder.py", line 199, in encode
    chunks = self.iterencode(o, _one_shot=True)
  File "C:\Users\Sahil Arora\AppData\Local\Programs\Python\Python36\lib\json\encoder.py", line 257, in iterencode
    return _iterencode(o, 0)
  File "C:\Users\Sahil Arora\Desktop\SCP-B\venv\lib\site-packages\rest_framework\utils\encoders.py", line 67, in default
    return super().default(obj)
  File "C:\Users\Sahil Arora\AppData\Local\Programs\Python\Python36\lib\json\encoder.py", line 180, in default
    o.__class__.__name__)
TypeError: Object of type 'property' is not JSON serializable
2020-09-24 14:44:15,126 WARNING  [log.py:228] Not Found: /verifyEmailID/
2020-09-24 14:44:25,996 ERROR    [log.py:228] Internal Server Error: /confirmEmailID/
Traceback (most recent call last):
  File "C:\Users\Sahil Arora\Desktop\SCP-B\venv\lib\site-packages\django\core\handlers\exception.py", line 34, in inner
    response = get_response(request)
  File "C:\Users\Sahil Arora\Desktop\SCP-B\venv\lib\site-packages\django\core\handlers\base.py", line 145, in _get_response
    response = self.process_exception_by_middleware(e, request)
  File "C:\Users\Sahil Arora\Desktop\SCP-B\venv\lib\site-packages\django\core\handlers\base.py", line 143, in _get_response
    response = response.render()
  File "C:\Users\Sahil Arora\Desktop\SCP-B\venv\lib\site-packages\django\template\response.py", line 105, in render
    self.content = self.rendered_content
  File "C:\Users\Sahil Arora\Desktop\SCP-B\venv\lib\site-packages\rest_framework\response.py", line 70, in rendered_content
    ret = renderer.render(self.data, accepted_media_type, context)
  File "C:\Users\Sahil Arora\Desktop\SCP-B\venv\lib\site-packages\rest_framework\renderers.py", line 103, in render
    allow_nan=not self.strict, separators=separators
  File "C:\Users\Sahil Arora\Desktop\SCP-B\venv\lib\site-packages\rest_framework\utils\json.py", line 25, in dumps
    return json.dumps(*args, **kwargs)
  File "C:\Users\Sahil Arora\AppData\Local\Programs\Python\Python36\lib\json\__init__.py", line 238, in dumps
    **kw).encode(obj)
  File "C:\Users\Sahil Arora\AppData\Local\Programs\Python\Python36\lib\json\encoder.py", line 199, in encode
    chunks = self.iterencode(o, _one_shot=True)
  File "C:\Users\Sahil Arora\AppData\Local\Programs\Python\Python36\lib\json\encoder.py", line 257, in iterencode
    return _iterencode(o, 0)
  File "C:\Users\Sahil Arora\Desktop\SCP-B\venv\lib\site-packages\rest_framework\utils\encoders.py", line 67, in default
    return super().default(obj)
  File "C:\Users\Sahil Arora\AppData\Local\Programs\Python\Python36\lib\json\encoder.py", line 180, in default
    o.__class__.__name__)
TypeError: Object of type 'property' is not JSON serializable
2020-09-24 14:44:40,654 WARNING  [log.py:228] Not Found: /verifyEmailID/
2020-09-24 14:46:30,614 INFO     [views.py:86] Trying: POST: User Registration data..
2020-09-24 14:46:30,650 INFO     [views.py:90] Successful: POST: User got saved.. 201 
2020-09-24 14:58:06,370 ERROR    [log.py:228] Internal Server Error: /confirmEmailID/
Traceback (most recent call last):
  File "C:\Users\Sahil Arora\Desktop\SCP-B\venv\lib\site-packages\django\core\handlers\exception.py", line 34, in inner
    response = get_response(request)
  File "C:\Users\Sahil Arora\Desktop\SCP-B\venv\lib\site-packages\django\core\handlers\base.py", line 145, in _get_response
    response = self.process_exception_by_middleware(e, request)
  File "C:\Users\Sahil Arora\Desktop\SCP-B\venv\lib\site-packages\django\core\handlers\base.py", line 143, in _get_response
    response = response.render()
  File "C:\Users\Sahil Arora\Desktop\SCP-B\venv\lib\site-packages\django\template\response.py", line 105, in render
    self.content = self.rendered_content
  File "C:\Users\Sahil Arora\Desktop\SCP-B\venv\lib\site-packages\rest_framework\response.py", line 70, in rendered_content
    ret = renderer.render(self.data, accepted_media_type, context)
  File "C:\Users\Sahil Arora\Desktop\SCP-B\venv\lib\site-packages\rest_framework\renderers.py", line 103, in render
    allow_nan=not self.strict, separators=separators
  File "C:\Users\Sahil Arora\Desktop\SCP-B\venv\lib\site-packages\rest_framework\utils\json.py", line 25, in dumps
    return json.dumps(*args, **kwargs)
  File "C:\Users\Sahil Arora\AppData\Local\Programs\Python\Python36\lib\json\__init__.py", line 238, in dumps
    **kw).encode(obj)
  File "C:\Users\Sahil Arora\AppData\Local\Programs\Python\Python36\lib\json\encoder.py", line 199, in encode
    chunks = self.iterencode(o, _one_shot=True)
  File "C:\Users\Sahil Arora\AppData\Local\Programs\Python\Python36\lib\json\encoder.py", line 257, in iterencode
    return _iterencode(o, 0)
  File "C:\Users\Sahil Arora\Desktop\SCP-B\venv\lib\site-packages\rest_framework\utils\encoders.py", line 67, in default
    return super().default(obj)
  File "C:\Users\Sahil Arora\AppData\Local\Programs\Python\Python36\lib\json\encoder.py", line 180, in default
    o.__class__.__name__)
TypeError: Object of type 'property' is not JSON serializable
2020-09-24 14:59:37,945 INFO     [views.py:86] Trying: POST: User Registration data..
2020-09-24 14:59:37,982 ERROR    [views.py:93] Failed: POST: to save User Register data.. 400
2020-09-24 14:59:37,984 WARNING  [log.py:228] Bad Request: /loginData/
2020-09-24 14:59:49,997 INFO     [views.py:86] Trying: POST: User Registration data..
2020-09-24 14:59:50,6 ERROR    [views.py:93] Failed: POST: to save User Register data.. 400
2020-09-24 14:59:50,7 WARNING  [log.py:228] Bad Request: /loginData/
2020-09-24 15:01:31,444 INFO     [views.py:78] Trying to get User Login Data....
2020-09-24 15:01:31,445 INFO     [views.py:81] Successfully got the User Login Data  201
2020-09-24 15:01:37,137 INFO     [views.py:78] Trying to get User Login Data....
2020-09-24 15:01:37,137 INFO     [views.py:81] Successfully got the User Login Data  201
2020-09-24 15:02:57,739 INFO     [views.py:86] Trying: POST: User Registration data..
2020-09-24 15:02:57,803 INFO     [views.py:90] Successful: POST: User got saved.. 201 
2020-09-24 15:03:16,28 INFO     [views.py:101] Trying: GET: User data by rollNumber MT2019096
2020-09-24 15:03:16,37 INFO     [views.py:111] Successful: GET: User data by rollNumber MT2019096
2020-09-24 17:15:37,823 INFO     [views.py:86] Trying: POST: User Registration data..
2020-09-24 17:15:37,852 INFO     [views.py:90] Successful: POST: User got saved.. 201 
2020-09-24 17:17:18,158 WARNING  [log.py:228] Not Found: /verifyEmailID/
2020-09-24 17:29:14,949 WARNING  [log.py:228] Not Found: /verifyEmailID/
2020-09-24 17:34:28,739 INFO     [views.py:101] Trying: GET: User data by rollNumber SRAVYA
2020-09-24 17:34:28,752 WARNING  [log.py:228] Not Found: /loginData/SRAVYA/
2020-09-24 17:34:50,1 INFO     [views.py:101] Trying: GET: User data by rollNumber MT2019114
2020-09-24 17:34:50,12 INFO     [views.py:111] Successful: GET: User data by rollNumber MT2019114
2020-09-26 12:38:20,153 INFO     [views.py:86] Trying: POST: User Registration data..
2020-09-26 12:38:20,226 INFO     [views.py:90] Successful: POST: User got saved.. 201 
